Workbook
Name After_tax_cost_of_debt: WACC!$D$6
Name Beta: WACC!$D$10
Name Comp_multiple: Multiples!$S$10
Name Cost_of_debt: WACC!$D$4
Name Cost_of_equity: WACC!$D$12
Name Marginal_tax_rate: WACC!$D$5
Name Market_risk_premium: WACC!$D$11
Name Market_value_of_equity: WACC!$D$16
Name Number_of_days_in_period: Assumptions!$C$2
Name Risk_free_rate: WACC!$D$9
Name Total_capital: WACC!$D$17
Name Total_debt: WACC!$D$15
Name UFCF_Yr5: DCF!$J$23
Name WACC: WACC!$D$19
Name Yr5_EBITDA: DCF!$J$10

Sheet Instructions
A2: Notes:
A3: ● Yellow cells are for data input (Assumptions & Perpetuity tabs)
A4: ● Blue text is for historical numbers (can be changed)
A5: ● Black text is for formulas (Not to be altered)
A6: ● You may need to press F9 to update the data tables
A9: Tab Navigation (Click to navigate)
A10: WACC: | B10: Weighted average cost of capital calculations & sensitivity analyses
A11: Assumptions: | B11: Operating, Capital Expenditure, & Working Capital Assumptions
A12: NWC: | B12: Net Working Capital forecasts and calculations to determine NWC
A13: DCF: | B13: Discounted Cash Flow Analysis & sensitivity analyses
A14: Multiples: | B14: Multiples Valuation

Sheet WACC
A1: *Note: Do not change any non-yellow cells
B3: Cost of debt: | H3: Beta increment | I3: 0.05 | L3: Beta increment | M3: 0.05
C4: Cost of debt | D4: 0.07 | L4: Risk Prem increment | M4: 0.0025
C5: Marginal tax rate | D5: 0.4
C6: After-tax cost of debt | D6: =D4*(1-D5) -> 0.042 | H6: WACC SENSITIVITY ANALYSIS to Beta | L6: WACC SENSITIVITY ANALYSIS (BETA + MARKET RISK PREMIUM)
H7: Beta | I7: WACC | M7: Market Risk Premium
B8: Cost of equity: | I8: =WACC -> 0.098564437 | L8: =WACC -> 0.098564437 | M8: 0.0605 | N8: =M8+$M$4 -> 0.063 | O8: =N8+$M$4 -> 0.0655 | P8: =O8+$M$4 -> 0.068 | Q8: =P8+$M$4 -> 0.0705 | R8: =Q8+$M$4 -> 0.073 | S8: =R8+$M$4 -> 0.0755 | T8: =S8+$M$4 -> 0.078 | U8: =T8+$M$4 -> 0.0805 | ... W8: =V8+$M$4 -> 0.0855
C9: Risk free rate | D9: 0.025 | H9: 0.35 | I9: 0.047954151 | K9: Beta | L9: 0.35 | M9: 0.045655674 | N9: 0.046421833 | O9: 0.047187992 | P9: 0.047954151 | Q9: 0.04872031 | R9: 0.04948647 | S9: 0.050252629 | T9: 0.051018788 | U9: 0.051784947 | V9: 0.052551106 | W9: 0.053317265
C10: Beta | D10: 1.2 | H10: =H9+$I$3 -> 0.4 | I10: 0.050931227 | L10: =L9+$M$3 -> 0.4 | M10: 0.048304395 | N10: 0.049180006 | O10: 0.050055616 | P10: 0.050931227 | Q10: 0.051806837 | R10: 0.052682448 | S10: 0.053558058 | T10: 0.054433669 | U10: 0.055309279 | V10: 0.05618489 | W10: 0.0570605
C11: Market risk premium | D11: 0.068 | H11: =H10+$I$3 -> 0.45 | I11: 0.053908302 | L11: =L10+$M$3 -> 0.45 | M11: 0.050953117 | N11: 0.051938179 | O11: 0.052923241 | P11: 0.053908302 | Q11: 0.054893364 | R11: 0.055878426 | S11: 0.056863488 | T11: 0.05784855 | U11: 0.058833611 | V11: 0.059818673 | W11: 0.060803735
C12: Cost of equity | D12: =D9+(D10*D11) -> 0.1066 | H12: =H11+$I$3 -> 0.5 | I12: 0.056885378 | L12: =L11+$M$3 -> 0.5 | M12: 0.053601839 | N12: 0.054696352 | O12: 0.055790865 | P12: 0.056885378 | Q12: 0.057979891 | R12: 0.059074404 | S12: 0.060168917 | T12: 0.06126343 | U12: 0.062357944 | V12: 0.063452457 | W12: 0.06454697
H13: =H12+$I$3 -> 0.55 | I13: 0.059862454 | L13: =L12+$M$3 -> 0.55 | M13: 0.05625056 | N13: 0.057454525 | O13: 0.058658489 | P13: 0.059862454 | Q13: 0.061066418 | R13: 0.062270382 | S13: 0.063474347 | T13: 0.064678311 | U13: 0.065882276 | V13: 0.06708624 | W13: 0.068290204
B14: Percentage of capital: | H14: =H13+$I$3 -> 0.6 | I14: 0.062839529 | L14: =L13+$M$3 -> 0.6 | M14: 0.058899282 | N14: 0.060212698 | O14: 0.061526114 | P14: 0.062839529 | Q14: 0.064152945 | R14: 0.065466361 | S14: 0.066779776 | T14: 0.068093192 | U14: 0.069406608 | V14: 0.070720024 | W14: 0.072033439
C15: Total debt | D15: 1945.9 | E15: =IFERROR(D15/$D$17,"") -> 0.12438953 | H15: =H14+$I$3 -> 0.65 | I15: 0.065816605 | L15: =L14+$M$3 -> 0.65 | M15: 0.061548004 | N15: 0.062970871 | O15: 0.064393738 | P15: 0.065816605 | Q15: 0.067239472 | R15: 0.068662339 | S15: 0.070085206 | T15: 0.071508073 | U15: 0.07293094 | V15: 0.074353807 | W15: 0.075776674
C16: Market value of equity | D16: 13697.7 | E16: =IFERROR(D16/$D$17,"") -> 0.87561047 | H16: =H15+$I$3 -> 0.7 | I16: 0.06879368 | L16: =L15+$M$3 -> 0.7 | M16: 0.064196725 | N16: 0.065729044 | O16: 0.067261362 | P16: 0.06879368 | Q16: 0.070325999 | R16: 0.071858317 | S16: 0.073390635 | T16: 0.074922954 | U16: 0.076455272 | V16: 0.07798759 | W16: 0.079519909
C17: Total capital | D17: =SUM(D15:D16) -> 15643.6 | E17: =SUM(E15:E16) -> 1 | H17: =H16+$I$3 -> 0.75 | I17: 0.071770756 | L17: =L16+$M$3 -> 0.75 | M17: 0.066845447 | N17: 0.068487217 | O17: 0.070128986 | P17: 0.071770756 | Q17: 0.073412526 | R17: 0.075054295 | S17: 0.076696065 | T17: 0.078337835 | U17: 0.079979604 | V17: 0.081621374 | W17: 0.083263144
H18: =H17+$I$3 -> 0.8 | I18: 0.074747832 | L18: =L17+$M$3 -> 0.8 | M18: 0.069494169 | N18: 0.07124539 | O18: 0.072996611 | P18: 0.074747832 | Q18: 0.076499053 | R18: 0.078250274 | S18: 0.080001495 | T18: 0.081752715 | U18: 0.083503936 | V18: 0.085255157 | W18: 0.087006378
C19: WACC | D19: =IFERROR((D6*E15) + (D12*E16),"") -> 0.098564437 | H19: =H18+$I$3 -> 0.85 | I19: 0.077724907 | L19: =L18+$M$3 -> 0.85 | M19: 0.072142891 | N19: 0.074003563 | O19: 0.075864235 | P19: 0.077724907 | Q19: 0.07958558 | R19: 0.081446252 | S19: 0.083306924 | T19: 0.085167596 | U19: 0.087028269 | V19: 0.088888941 | W19: 0.090749613
H20: =H19+$I$3 -> 0.9 | I20: 0.080701983 | L20: =L19+$M$3 -> 0.9 | M20: 0.074791612 | N20: 0.076761736 | O20: 0.078731859 | P20: 0.080701983 | Q20: 0.082672106 | R20: 0.08464223 | S20: 0.086612354 | T20: 0.088582477 | U20: 0.090552601 | V20: 0.092522724 | W20: 0.094492848
H21: =H20+$I$3 -> 0.95 | I21: 0.083679059 | L21: =L20+$M$3 -> 0.95 | M21: 0.077440334 | N21: 0.079519909 | O21: 0.081599484 | P21: 0.083679059 | Q21: 0.085758633 | R21: 0.087838208 | S21: 0.089917783 | T21: 0.091997358 | U21: 0.094076933 | V21: 0.096156508 | W21: 0.098236083
H22: =H21+$I$3 -> 1 | I22: 0.086656134 | L22: =L21+$M$3 -> 1 | M22: 0.080089056 | N22: 0.082278082 | O22: 0.084467108 | P22: 0.086656134 | Q22: 0.08884516 | R22: 0.091034187 | S22: 0.093223213 | T22: 0.095412239 | U22: 0.097601265 | V22: 0.099790291 | W22: 0.10197932
H23: =H22+$I$3 -> 1.05 | I23: 0.08963321 | L23: =L22+$M$3 -> 1.05 | M23: 0.082737777 | N23: 0.085036255 | O23: 0.087334732 | P23: 0.08963321 | Q23: 0.091931687 | R23: 0.094230165 | S23: 0.096528642 | T23: 0.09882712 | U23: 0.1011256 | V23: 0.10342407 | W23: 0.10572255
H24: =H23+$I$3 -> 1.1 | I24: 0.092610285

Sheet Assumptions
A1: *Note: Do not change any non-yellow cells or non-blue text
B2: Number of days in period: | C2: 365
C4: Historical | F4: Projected
C5: 2023 | D5: 2024 | E5: 2025 | F5: =E5+1 -> 2026 | G5: =F5+1 -> 2027 | H5: =G5+1 -> 2028 | I5: =H5+1 -> 2029 | J5: =I5+1 -> 2030
A6: DCF tab
A7: Operating Assumptions
B8: Sales growth | C8: NA | D8: 0.08 | E8: 0.13 | F8: 0.04 | G8: 0.04 | H8: 0.04 | I8: 0.04 | J8: 0.04
B9: Cost of goods sold (as a % sales) | C9: 0.38 | D9: 0.15 | E9: 0.33 | F9: =AVERAGE(C9:E9) -> 0.28666667 | G9: =F9 -> 0.28666667 | H9: =G9 -> 0.28666667 | I9: =H9 -> 0.28666667 | J9: =I9 -> 0.28666667
B10: SG&A (as a % sales) | C10: 0.15 | D10: 0.13 | E10: 0.17 | F10: =AVERAGE(C10:E10) -> 0.15 | G10: =F10 -> 0.15 | H10: =G10 -> 0.15 | I10: =H10 -> 0.15 | J10: =I10 -> 0.15
A11: Capital Expenditure Assumptions
B12: CapEx (as a % sales) | C12: NA | D12: 0.03 | E12: 0.05 | F12: =AVERAGE(C12:E12) -> 0.04 | G12: =F12 -> 0.04 | H12: =G12 -> 0.04 | I12: =H12 -> 0.04 | J12: =I12 -> 0.04
B13: Depreciation (as a % of CapEx) | C13: NA | D13: 0.55 | E13: 0.55 | F13: =AVERAGE(C13:E13) -> 0.55 | G13: =F13 -> 0.55 | H13: =G13 -> 0.55 | I13: =H13 -> 0.55 | J13: =I13 -> 0.55
B15: Additions to Intangibles ($ amount) | C15: NA | D15: 15 | E15: 15 | F15: =E15 -> 15 | G15: =F15 -> 15 | H15: =G15 -> 15 | I15: =H15 -> 15 | J15: =I15 -> 15
B16: Amortization ($ amount) | C16: NA | D16: 7 | E16: 7 | F16: =E16 -> 7 | G16: =F16 -> 7 | H16: =G16 -> 7 | I16: =H16 -> 7 | J16: =I16 -> 7
A18: Working Capital tab (NWC)
A19: Working Capital Assumptions
B20: Accounts receivable (days collection period) | C20: 37.262215 | D20: 32.369857 | E20: 32.100326 | F20: =AVERAGE(C20:E20) -> 33.910799 | G20: =F20 -> 33.910799 | H20: =G20 -> 33.910799 | I20: =H20 -> 33.910799 | J20: =I20 -> 33.910799
B21: Inventories (days outstanding) | C21: 77 | D21: 65 | E21: 71 | F21: =AVERAGE(C21:E21) -> 71 | G21: =F21 -> 71 | H21: =G21 -> 71 | I21: =H21 -> 71 | J21: =I21 -> 71
B22: Accounts payable (days outstanding) | C22: 44 | D22: 55 | E22: 66 | F22: =AVERAGE(C22:E22) -> 55 | G22: =F22 -> 55 | H22: =G22 -> 55 | I22: =H22 -> 55 | J22: =I22 -> 55
B24: Other current assets (as % of sales) | C24: 0.05 | D24: 0.055 | E24: 0.051 | F24: =AVERAGE(C24:E24) -> 0.052 | G24: =F24 -> 0.052 | H24: =G24 -> 0.052 | I24: =H24 -> 0.052 | J24: =I24 -> 0.052
B25: Accrued liabilities (as % of sales) | C25: 0.08 | D25: 0.11 | E25: 0.07 | F25: =AVERAGE(C25:E25) -> 0.086666667 | G25: =F25 -> 0.086666667 | H25: =G25 -> 0.086666667 | I25: =H25 -> 0.086666667 | J25: =I25 -> 0.086666667
B26: Other current liabilities (as % of sales) | C26: 0.01 | D26: 0.008 | E26: 0.00655 | F26: =AVERAGE(C26:E26) -> 0.0081833333 | G26: =F26 -> 0.0081833333 | H26: =G26 -> 0.0081833333 | I26: =H26 -> 0.0081833333 | J26: =I26 -> 0.0081833333

Sheet NWC
A1: *Note: Do not change any non-yellow cells or non-blue text
C3: Historical | F3: Projected
C4: =DCF!C4 -> 2023 | D4: =DCF!D4 -> 2024 | E4: =DCF!E4 -> 2025 | F4: =DCF!F4 -> 2026 | G4: =DCF!G4 -> 2027 | H4: =DCF!H4 -> 2028 | I4: =DCF!I4 -> 2029 | J4: =DCF!J4 -> 2030
A6: Sales | C6: =DCF!C5 -> 4946.7 | D6: =DCF!D5 -> 5342.436 | E6: =DCF!E5 -> 6036.9527 | F6: =DCF!F5 -> 6278.4308 | G6: =DCF!G5 -> 6529.568 | H6: =DCF!H5 -> 6790.7507 | I6: =DCF!I5 -> 7062.3808 | J6: =DCF!J5 -> 7344.876
A7: Cost of goods sold | C7: =DCF!C6 -> 3192.1 | D7: =DCF!D6 -> 801.3654 | E7: =DCF!E6 -> 1992.1944 | F7: =DCF!F6 -> 1799.8168 | G7: =DCF!G6 -> 1871.8095 | H7: =DCF!H6 -> 1946.6819 | I7: =DCF!I6 -> 2024.5492 | J7: =DCF!J6 -> 2105.5311
B9: Accounts receivable, net | C9: =(C6*Assumptions!C20)/Number_of_days_in_period -> 505 | D9: =(D6*Assumptions!D20)/Number_of_days_in_period -> 473.79147 | E9: =(E6*Assumptions!E20)/Number_of_days_in_period -> 530.92644 | F9: =(F6*Assumptions!F20)/Number_of_days_in_period -> 583.30577 | G9: =(G6*Assumptions!G20)/Number_of_days_in_period -> 606.638 | H9: =(H6*Assumptions!H20)/Number_of_days_in_period -> 630.90352 | I9: =(I6*Assumptions!I20)/Number_of_days_in_period -> 656.13967 | J9: =(J6*Assumptions!J20)/Number_of_days_in_period -> 682.38525
B10: Inventories | C10: =(C7*Assumptions!C21)/Number_of_days_in_period -> 673.40192 | D10: =(D7*Assumptions!D21)/Number_of_days_in_period -> 142.70891 | E10: =(E7*Assumptions!E21)/Number_of_days_in_period -> 387.52274 | F10: =(F7*Assumptions!F21)/Number_of_days_in_period -> 350.10136 | G10: =(G7*Assumptions!G21)/Number_of_days_in_period -> 364.10541 | H10: =(H7*Assumptions!H21)/Number_of_days_in_period -> 378.66963 | I10: =(I7*Assumptions!I21)/Number_of_days_in_period -> 393.81641 | J10: =(J7*Assumptions!J21)/Number_of_days_in_period -> 409.56907
B11: Other current assets | C11: =C6*Assumptions!C24 -> 247.335 | D11: =D6*Assumptions!D24 -> 293.83398 | E11: =E6*Assumptions!E24 -> 307.88459 | F11: =F6*Assumptions!F24 -> 326.4784 | G11: =G6*Assumptions!G24 -> 339.53754 | H11: =H6*Assumptions!H24 -> 353.11904 | I11: =I6*Assumptions!I24 -> 367.2438 | J11: =J6*Assumptions!J24 -> 381.93355
B12: Total non-cash current assets: | C12: =SUM(C9:C11) -> 1425.7369 | D12: =SUM(D9:D11) -> 910.33436 | E12: =SUM(E9:E11) -> 1226.3338 | F12: =SUM(F9:F11) -> 1259.8855 | G12: =SUM(G9:G11) -> 1310.281 | H12: =SUM(H9:H11) -> 1362.6922 | I12: =SUM(I9:I11) -> 1417.1999 | J12: =SUM(J9:J11) -> 1473.8879
B14: Accounts payable | C14: =(C7*Assumptions!C22)/Number_of_days_in_period -> 384.8011 | D14: =(D7*Assumptions!D22)/Number_of_days_in_period -> 120.75369 | E14: =(E7*Assumptions!E22)/Number_of_days_in_period -> 360.23241 | F14: =(F7*Assumptions!F22)/Number_of_days_in_period -> 271.20528 | G14: =(G7*Assumptions!G22)/Number_of_days_in_period -> 282.05349 | H14: =(H7*Assumptions!H22)/Number_of_days_in_period -> 293.33563 | I14: =(I7*Assumptions!I22)/Number_of_days_in_period -> 305.06905 | J14: =(J7*Assumptions!J22)/Number_of_days_in_period -> 317.27181
B15: Accrued liabilities | C15: =C6*Assumptions!C25 -> 395.736 | D15: =D6*Assumptions!D25 -> 587.66796 | E15: =E6*Assumptions!E25 -> 422.58669 | F15: =F6*Assumptions!F25 -> 544.13067 | G15: =G6*Assumptions!G25 -> 565.89589 | H15: =H6*Assumptions!H25 -> 588.53173 | I15: =I6*Assumptions!I25 -> 612.073 | J15: =J6*Assumptions!J25 -> 636.55592
B16: Other current liabilities | C16: =C6*Assumptions!C26 -> 49.467 | D16: =D6*Assumptions!D26 -> 42.739488 | E16: =E6*Assumptions!E26 -> 39.54204 | F16: =F6*Assumptions!F26 -> 51.378492 | G16: =G6*Assumptions!G26 -> 53.433632 | H16: =H6*Assumptions!H26 -> 55.570977 | I16: =I6*Assumptions!I26 -> 57.793816 | J16: =J6*Assumptions!J26 -> 60.105569
B17: Total non-debt current liabilities | C17: =SUM(C14:C16) -> 830.0041 | D17: =SUM(D14:D16) -> 751.16114 | E17: =SUM(E14:E16) -> 822.36114 | F17: =SUM(F14:F16) -> 866.71444 | G17: =SUM(G14:G16) -> 901.38301 | H17: =SUM(H14:H16) -> 937.43833 | I17: =SUM(I14:I16) -> 974.93587 | J17: =SUM(J14:J16) -> 1013.9333
A19: Net working capital / (deficit) | C19: =C12-C17 -> 595.73282 | D19: =D12-D17 -> 159.17322 | E19: =E12-E17 -> 403.97264 | F19: =F12-F17 -> 393.17109 | G19: =G12-G17 -> 408.89794 | H19: =H12-H17 -> 425.25386 | I19: =I12-I17 -> 442.26401 | J19: =J12-J17 -> 459.95457
A21: Change in net working capital | D21: =D19-C19 -> -436.5596 | E21: =E19-D19 -> 244.79942 | F21: =F19-E19 -> -10.801543 | G21: =G19-F19 -> 15.726844 | H21: =H19-G19 -> 16.355918 | I21: =I19-H19 -> 17.010154 | J21: =J19-I19 -> 17.69056

Sheet DCF
A1: *Note: Do not change any non-yellow cells or non-blue text | G1: NPER: | H1: =Assumptions!J5-Assumptions!E5 -> 5
A2: Figures in millions, except per share
C3: Historical | F3: Projected
C4: =Assumptions!C5 -> 2023 | D4: =Assumptions!D5 -> 2024 | E4: =Assumptions!E5 -> 2025 | F4: =Assumptions!F5 -> 2026 | G4: =Assumptions!G5 -> 2027 | H4: =Assumptions!H5 -> 2028 | I4: =Assumptions!I5 -> 2029 | J4: =Assumptions!J5 -> 2030 | K4: CAGR
A5: Sales | C5: 4946.7 | D5: =C5*(1+Assumptions!D8) -> 5342.436 | E5: =D5*(1+Assumptions!E8) -> 6036.9527 | F5: =E5*(1+Assumptions!F8) -> 6278.4308 | G5: =F5*(1+Assumptions!G8) -> 6529.568 | H5: =G5*(1+Assumptions!H8) -> 6790.7507 | I5: =H5*(1+Assumptions!I8) -> 7062.3808 | J5: =I5*(1+Assumptions!J8) -> 7344.876 | K5: =IFERROR(RATE($J$4-$E$4,,-E5,J5),"") -> 0.04
A6: Cost of goods sold | C6: 3192.1 | D6: =D5*Assumptions!D9 -> 801.3654 | E6: =E5*Assumptions!E9 -> 1992.1944 | F6: =F5*Assumptions!F9 -> 1799.8168 | G6: =G5*Assumptions!G9 -> 1871.8095 | H6: =H5*Assumptions!H9 -> 1946.6819 | I6: =I5*Assumptions!I9 -> 2024.5492 | J6: =J5*Assumptions!J9 -> 2105.5311
A7: Gross Profit | C7: =C5-C6 -> 1754.6 | D7: =D5-D6 -> 4541.0706 | E7: =E5-E6 -> 4044.7583 | F7: =F5-F6 -> 4478.614 | G7: =G5-G6 -> 4657.7585 | H7: =H5-H6 -> 4844.0689 | I7: =I5-I6 -> 5037.8316 | J7: =J5-J6 -> 5239.3449 | K7: =IFERROR(RATE($J$4-$E$4,,-E7,J7),"") -> 0.053117628
A9: SG&A | C9: =C5*Assumptions!C10 -> 742.005 | D9: =D5*Assumptions!D10 -> 694.51668 | E9: =E5*Assumptions!E10 -> 1026.282 | F9: =F5*Assumptions!F10 -> 941.76462 | G9: =G5*Assumptions!G10 -> 979.4352 | H9: =H5*Assumptions!H10 -> 1018.6126 | I9: =I5*Assumptions!I10 -> 1059.3571 | J9: =J5*Assumptions!J10 -> 1101.7314
A10: EBITDA | C10: =C7-C9 -> 1012.595 | D10: =D7-D9 -> 3846.5539 | E10: =E7-E9 -> 3018.4763 | F10: =F7-F9 -> 3536.8493 | G10: =G7-G9 -> 3678.3233 | H10: =H7-H9 -> 3825.4562 | I10: =I7-I9 -> 3978.4745 | J10: =J7-J9 -> 4137.6135 | K10: =IFERROR(RATE($J$4-$E$4,,-E10,J10),"") -> 0.065105012
B11: EBITDA Margin | C11: =IFERROR(C10/C5,"") -> 0.20470111 | D11: =IFERROR(D10/D5,"") -> 0.72 | E11: =IFERROR(E10/E5,"") -> 0.5 | F11: =IFERROR(F10/F5,"") -> 0.56333333 | G11: =IFERROR(G10/G5,"") -> 0.56333333 | H11: =IFERROR(H10/H5,"") -> 0.56333333 | I11: =IFERROR(I10/I5,"") -> 0.56333333 | J11: =IFERROR(J10/J5,"") -> 0.56333333
A13: Less: Depreciation | C13: 199.3 | D13: =D20*Assumptions!D13 -> 88.150194 | E13: =E20*Assumptions!E13 -> 166.0162 | F13: =F20*Assumptions!F13 -> 138.12548 | G13: =G20*Assumptions!G13 -> 143.6505 | H13: =H20*Assumptions!H13 -> 149.39652 | I13: =I20*Assumptions!I13 -> 155.37238 | J13: =J20*Assumptions!J13 -> 161.58727
A14: Less: Amortization | C14: 3 | D14: =Assumptions!D16 -> 7 | E14: =Assumptions!E16 -> 7 | F14: =Assumptions!F16 -> 7 | G14: =Assumptions!G16 -> 7 | H14: =Assumptions!H16 -> 7 | I14: =Assumptions!I16 -> 7 | J14: =Assumptions!J16 -> 7
A15: EBIT | C15: =C10-SUM(C13:C14) -> 810.295 | D15: =D10-SUM(D13:D14) -> 3751.4037 | E15: =E10-SUM(E13:E14) -> 2845.4601 | F15: =F10-SUM(F13:F14) -> 3391.7239 | G15: =G10-SUM(G13:G14) -> 3527.6728 | H15: =H10-SUM(H13:H14) -> 3669.0597 | I15: =I10-SUM(I13:I14) -> 3816.1021 | J15: =J10-SUM(J13:J14) -> 3969.0262 | K15: =IFERROR(RATE($J$4-$E$4,,-E15,J15),"") -> 0.068824234
A16: ="Less: Taxes @ "&Marginal_tax_rate*100&"%" -> Less: Taxes @ 40% | C16: =C15*Marginal_tax_rate -> 324.118 | D16: =D15*Marginal_tax_rate -> 1500.5615 | E16: =E15*Marginal_tax_rate -> 1138.1841 | F16: =F15*Marginal_tax_rate -> 1356.6895 | G16: =G15*Marginal_tax_rate -> 1411.0691 | H16: =H15*Marginal_tax_rate -> 1467.6239 | I16: =I15*Marginal_tax_rate -> 1526.4408 | J16: =J15*Marginal_tax_rate -> 1587.6105
A17: Tax-effected EBIT | C17: =C15-C16 -> 486.177 | D17: =D15-D16 -> 2250.8422 | E17: =E15-E16 -> 1707.2761 | F17: =F15-F16 -> 2035.0343 | G17: =G15-G16 -> 2116.6037 | H17: =H15-H16 -> 2201.4358 | I17: =I15-I16 -> 2289.6613 | J17: =J15-J16 -> 2381.4157 | K17: =IFERROR(RATE($J$4-$E$4,,-E17,J17),"") -> 0.068824234
A19: Plus: Depreciation and amortization | D19: =D13+D14 -> 95.150194 | E19: =E13+E14 -> 173.0162 | F19: =F13+F14 -> 145.12548 | G19: =G13+G14 -> 150.6505 | H19: =H13+H14 -> 156.39652 | I19: =I13+I14 -> 162.37238 | J19: =J13+J14 -> 168.58727
A20: Less: Capital expenditures | D20: =D5*Assumptions!D12 -> 160.27308 | E20: =E5*Assumptions!E12 -> 301.84763 | F20: =F5*Assumptions!F12 -> 251.13723 | G20: =G5*Assumptions!G12 -> 261.18272 | H20: =H5*Assumptions!H12 -> 271.63003 | I20: =I5*Assumptions!I12 -> 282.49523 | J20: =J5*Assumptions!J12 -> 293.79504
A21: Less: Additions to intangibles | D21: =Assumptions!D15 -> 15 | E21: =Assumptions!E15 -> 15 | F21: =Assumptions!F15 -> 15 | G21: =Assumptions!G15 -> 15 | H21: =Assumptions!H15 -> 15 | I21: =Assumptions!I15 -> 15 | J21: =Assumptions!J15 -> 15
A22: Plus: Change in working capital | D22: =NWC!D21 -> -436.5596 | E22: =NWC!E21 -> 244.79942 | F22: =NWC!F21 -> -10.801543 | G22: =NWC!G21 -> 15.726844 | H22: =NWC!H21 -> 16.355918 | I22: =NWC!I21 -> 17.010154 | J22: =NWC!J21 -> 17.69056
A23: Unlevered Free Cash Flow | D23: =D17+D19-D20-D21-D22 -> 2607.279 | E23: =E17+E19-E20-E21-E22 -> 1318.6452 | F23: =F17+F19-F20-F21-F22 -> 1924.8241 | G23: =G17+G19-G20-G21-G22 -> 1975.3446 | H23: =H17+H19-H20-H21-H22 -> 2054.8464 | I23: =I17+I19-I20-I21-I22 -> 2137.5283 | J23: =J17+J19-J20-J21-J22 -> 2223.5174 | K23: =IFERROR(RATE($J$4-$E$4,,-E23,J23),"") -> 0.11015217
A24: TV
B26: Perpetuity Growth Method | H26: Price Sensitivity Analysis
B28: WACC | C28: =WACC -> 0.098564437 | H28: Terminal Growth Rate increment
B29: NPV(FCF) | C29: =NPV(C28,F23:J23) -> 7796.0897 | H29: 0.005
H30: WACC increment
B31: Terminal growth rate | C31: 0.025 | H31: 0.005
B32: Terminal value | C32: =(UFCF_Yr5*(1+C31))/(WACC-C31) -> 30981.075
B33: PV(Terminal value) | C33: =PV(WACC,H1,,-C32,0) -> 19362.829 | H33: WACC
G34: =C41 -> 128.43758 | H34: 0.045 | I34: =H34+$H$31 -> 0.05 | J34: =I34+$H$31 -> 0.055 | K34: =J34+$H$31 -> 0.06 | L34: =K34+$H$31 -> 0.065 | M34: =L34+$H$31 -> 0.07 | N34: =M34+$H$31 -> 0.075 | O34: =N34+$H$31 -> 0.08 | P34: =O34+$H$31 -> 0.085 | Q34: =P34+$H$31 -> 0.09
B35: Enterprise value | C35: =C29+C33 -> 27158.918 | F35: Terminal Growth Rate | G35: 0.025 | H35: =IFERROR((NPV(H$34,$F$23:$J$23) + PV(H$34,$H$1,,-(UFCF_Yr5*(1+$G35)/(H$34-$G35)),0) - $C$36)/$C$39, "Error") -> 493.09075 | I35: =IFERROR((NPV(I$34,$F$23:$J$23) + PV(I$34,$H$1,,-(UFCF_Yr5*(1+$G35)/(I$34-$G35)),0) - $C$36)/$C$39, "Error") -> 392.90814 | J35: =IFERROR((NPV(J$34,$F$23:$J$23) + PV(J$34,$H$1,,-(UFCF_Yr5*(1+$G35)/(J$34-$G35)),0) - $C$36)/$C$39, "Error") -> 326.1236 | K35: =IFERROR((NPV(K$34,$F$23:$J$23) + PV(K$34,$H$1,,-(UFCF_Yr5*(1+$G35)/(K$34-$G35)),0) - $C$36)/$C$39, "Error") -> 278.42359 | L35: =IFERROR((NPV(L$34,$F$23:$J$23) + PV(L$34,$H$1,,-(UFCF_Yr5*(1+$G35)/(L$34-$G35)),0) - $C$36)/$C$39, "Error") -> 242.65134 | M35: =IFERROR((NPV(M$34,$F$23:$J$23) + PV(M$34,$H$1,,-(UFCF_Yr5*(1+$G35)/(M$34-$G35)),0) - $C$36)/$C$39, "Error") -> 214.83086 | N35: =IFERROR((NPV(N$34,$F$23:$J$23) + PV(N$34,$H$1,,-(UFCF_Yr5*(1+$G35)/(N$34-$G35)),0) - $C$36)/$C$39, "Error") -> 192.57658 | O35: =IFERROR((NPV(O$34,$F$23:$J$23) + PV(O$34,$H$1,,-(UFCF_Yr5*(1+$G35)/(O$34-$G35)),0) - $C$36)/$C$39, "Error") -> 174.3704 | ... Q35: =IFERROR((NPV(Q$34,$F$23:$J$23) + PV(Q$34,$H$1,,-(UFCF_Yr5*(1+$G35)/(Q$34-$G35)),0) - $C$36)/$C$39, "Error") -> 146.36545
B36: Less: Net debt* | C36: 1336.8 | G36: =G35+$H$29 -> 0.03 | H36: =IFERROR((NPV(H$34,$F$23:$J$23) + PV(H$34,$H$1,,-(UFCF_Yr5*(1+$G36)/(H$34-$G36)),0) - $C$36)/$C$39, "Error") -> 647.66045 | I36: =IFERROR((NPV(I$34,$F$23:$J$23) + PV(I$34,$H$1,,-(UFCF_Yr5*(1+$G36)/(I$34-$G36)),0) - $C$36)/$C$39, "Error") -> 483.89603 | J36: =IFERROR((NPV(J$34,$F$23:$J$23) + PV(J$34,$H$1,,-(UFCF_Yr5*(1+$G36)/(J$34-$G36)),0) - $C$36)/$C$39, "Error") -> 385.64041 | K36: =IFERROR((NPV(K$34,$F$23:$J$23) + PV(K$34,$H$1,,-(UFCF_Yr5*(1+$G36)/(K$34-$G36)),0) - $C$36)/$C$39, "Error") -> 320.13914 | L36: =IFERROR((NPV(L$34,$F$23:$J$23) + PV(L$34,$H$1,,-(UFCF_Yr5*(1+$G36)/(L$34-$G36)),0) - $C$36)/$C$39, "Error") -> 273.35458 | M36: =IFERROR((NPV(M$34,$F$23:$J$23) + PV(M$34,$H$1,,-(UFCF_Yr5*(1+$G36)/(M$34-$G36)),0) - $C$36)/$C$39, "Error") -> 238.26792 | N36: =IFERROR((NPV(N$34,$F$23:$J$23) + PV(N$34,$H$1,,-(UFCF_Yr5*(1+$G36)/(N$34-$G36)),0) - $C$36)/$C$39, "Error") -> 210.97983 | O36: =IFERROR((NPV(O$34,$F$23:$J$23) + PV(O$34,$H$1,,-(UFCF_Yr5*(1+$G36)/(O$34-$G36)),0) - $C$36)/$C$39, "Error") -> 189.15069 | ... Q36: =IFERROR((NPV(Q$34,$F$23:$J$23) + PV(Q$34,$H$1,,-(UFCF_Yr5*(1+$G36)/(Q$34-$G36)),0) - $C$36)/$C$39, "Error") -> 156.41022
B37: Equity value | C37: =C35-C36 -> 25822.118 | G37: =G36+$H$29 -> 0.035 | H37: =IFERROR((NPV(H$34,$F$23:$J$23) + PV(H$34,$H$1,,-(UFCF_Yr5*(1+$G37)/(H$34-$G37)),0) - $C$36)/$C$39, "Error") -> 956.79985 | I37: =IFERROR((NPV(I$34,$F$23:$J$23) + PV(I$34,$H$1,,-(UFCF_Yr5*(1+$G37)/(I$34-$G37)),0) - $C$36)/$C$39, "Error") -> 635.5425 | J37: =IFERROR((NPV(J$34,$F$23:$J$23) + PV(J$34,$H$1,,-(UFCF_Yr5*(1+$G37)/(J$34-$G37)),0) - $C$36)/$C$39, "Error") -> 474.91563 | K37: =IFERROR((NPV(K$34,$F$23:$J$23) + PV(K$34,$H$1,,-(UFCF_Yr5*(1+$G37)/(K$34-$G37)),0) - $C$36)/$C$39, "Error") -> 378.54092 | L37: =IFERROR((NPV(L$34,$F$23:$J$23) + PV(L$34,$H$1,,-(UFCF_Yr5*(1+$G37)/(L$34-$G37)),0) - $C$36)/$C$39, "Error") -> 314.29225 | M37: =IFERROR((NPV(M$34,$F$23:$J$23) + PV(M$34,$H$1,,-(UFCF_Yr5*(1+$G37)/(M$34-$G37)),0) - $C$36)/$C$39, "Error") -> 268.40129 | N37: =IFERROR((NPV(N$34,$F$23:$J$23) + PV(N$34,$H$1,,-(UFCF_Yr5*(1+$G37)/(N$34-$G37)),0) - $C$36)/$C$39, "Error") -> 233.98388 | O37: =IFERROR((NPV(O$34,$F$23:$J$23) + PV(O$34,$H$1,,-(UFCF_Yr5*(1+$G37)/(O$34-$G37)),0) - $C$36)/$C$39, "Error") -> 207.21549 | ... Q37: =IFERROR((NPV(Q$34,$F$23:$J$23) + PV(Q$34,$H$1,,-(UFCF_Yr5*(1+$G37)/(Q$34-$G37)),0) - $C$36)/$C$39, "Error") -> 168.28132
G38: =G37+$H$29 -> 0.04 | H38: =IFERROR((NPV(H$34,$F$23:$J$23) + PV(H$34,$H$1,,-(UFCF_Yr5*(1+$G38)/(H$34-$G38)),0) - $C$36)/$C$39, "Error") -> 1884.218 | I38: =IFERROR((NPV(I$34,$F$23:$J$23) + PV(I$34,$H$1,,-(UFCF_Yr5*(1+$G38)/(I$34-$G38)),0) - $C$36)/$C$39, "Error") -> 938.83546 | J38: =IFERROR((NPV(J$34,$F$23:$J$23) + PV(J$34,$H$1,,-(UFCF_Yr5*(1+$G38)/(J$34-$G38)),0) - $C$36)/$C$39, "Error") -> 623.70767 | K38: =IFERROR((NPV(K$34,$F$23:$J$23) + PV(K$34,$H$1,,-(UFCF_Yr5*(1+$G38)/(K$34-$G38)),0) - $C$36)/$C$39, "Error") -> 466.14358 | L38: =IFERROR((NPV(L$34,$F$23:$J$23) + PV(L$34,$H$1,,-(UFCF_Yr5*(1+$G38)/(L$34-$G38)),0) - $C$36)/$C$39, "Error") -> 371.60497 | M38: =IFERROR((NPV(M$34,$F$23:$J$23) + PV(M$34,$H$1,,-(UFCF_Yr5*(1+$G38)/(M$34-$G38)),0) - $C$36)/$C$39, "Error") -> 308.57911 | N38: =IFERROR((NPV(N$34,$F$23:$J$23) + PV(N$34,$H$1,,-(UFCF_Yr5*(1+$G38)/(N$34-$G38)),0) - $C$36)/$C$39, "Error") -> 263.56053 | O38: =IFERROR((NPV(O$34,$F$23:$J$23) + PV(O$34,$H$1,,-(UFCF_Yr5*(1+$G38)/(O$34-$G38)),0) - $C$36)/$C$39, "Error") -> 229.7965 | ... Q38: =IFERROR((NPV(Q$34,$F$23:$J$23) + PV(Q$34,$H$1,,-(UFCF_Yr5*(1+$G38)/(Q$34-$G38)),0) - $C$36)/$C$39, "Error") -> 182.52663
B39: Diluted shares: | C39: 201.048 | G39: =G38+$H$29 -> 0.045 | H39: =IFERROR((NPV(H$34,$F$23:$J$23) + PV(H$34,$H$1,,-(UFCF_Yr5*(1+$G39)/(H$34-$G39)),0) - $C$36)/$C$39, "Error") -> Error | I39: =IFERROR((NPV(I$34,$F$23:$J$23) + PV(I$34,$H$1,,-(UFCF_Yr5*(1+$G39)/(I$34-$G39)),0) - $C$36)/$C$39, "Error") -> 1848.7143 | J39: =IFERROR((NPV(J$34,$F$23:$J$23) + PV(J$34,$H$1,,-(UFCF_Yr5*(1+$G39)/(J$34-$G39)),0) - $C$36)/$C$39, "Error") -> 921.29174 | K39: =IFERROR((NPV(K$34,$F$23:$J$23) + PV(K$34,$H$1,,-(UFCF_Yr5*(1+$G39)/(K$34-$G39)),0) - $C$36)/$C$39, "Error") -> 612.14802 | L39: =IFERROR((NPV(L$34,$F$23:$J$23) + PV(L$34,$H$1,,-(UFCF_Yr5*(1+$G39)/(L$34-$G39)),0) - $C$36)/$C$39, "Error") -> 457.57407 | M39: =IFERROR((NPV(M$34,$F$23:$J$23) + PV(M$34,$H$1,,-(UFCF_Yr5*(1+$G39)/(M$34-$G39)),0) - $C$36)/$C$39, "Error") -> 364.82806 | N39: =IFERROR((NPV(N$34,$F$23:$J$23) + PV(N$34,$H$1,,-(UFCF_Yr5*(1+$G39)/(N$34-$G39)),0) - $C$36)/$C$39, "Error") -> 302.99605 | O39: =IFERROR((NPV(O$34,$F$23:$J$23) + PV(O$34,$H$1,,-(UFCF_Yr5*(1+$G39)/(O$34-$G39)),0) - $C$36)/$C$39, "Error") -> 258.82922 | ... Q39: =IFERROR((NPV(Q$34,$F$23:$J$23) + PV(Q$34,$H$1,,-(UFCF_Yr5*(1+$G39)/(Q$34-$G39)),0) - $C$36)/$C$39, "Error") -> 199.93758
G40: =G39+$H$29 -> 0.05 | H40: =IFERROR((NPV(H$34,$F$23:$J$23) + PV(H$34,$H$1,,-(UFCF_Yr5*(1+$G40)/(H$34-$G40)),0) - $C$36)/$C$39, "Error") -> -1825.4547 | I40: =IFERROR((NPV(I$34,$F$23:$J$23) + PV(I$34,$H$1,,-(UFCF_Yr5*(1+$G40)/(I$34-$G40)),0) - $C$36)/$C$39, "Error") -> Error | J40: =IFERROR((NPV(J$34,$F$23:$J$23) + PV(J$34,$H$1,,-(UFCF_Yr5*(1+$G40)/(J$34-$G40)),0) - $C$36)/$C$39, "Error") -> 1814.044 | K40: =IFERROR((NPV(K$34,$F$23:$J$23) + PV(K$34,$H$1,,-(UFCF_Yr5*(1+$G40)/(K$34-$G40)),0) - $C$36)/$C$39, "Error") -> 904.1569 | L40: =IFERROR((NPV(L$34,$F$23:$J$23) + PV(L$34,$H$1,,-(UFCF_Yr5*(1+$G40)/(L$34-$G40)),0) - $C$36)/$C$39, "Error") -> 600.85589 | M40: =IFERROR((NPV(M$34,$F$23:$J$23) + PV(M$34,$H$1,,-(UFCF_Yr5*(1+$G40)/(M$34-$G40)),0) - $C$36)/$C$39, "Error") -> 449.20148 | N40: =IFERROR((NPV(N$34,$F$23:$J$23) + PV(N$34,$H$1,,-(UFCF_Yr5*(1+$G40)/(N$34-$G40)),0) - $C$36)/$C$39, "Error") -> 358.20579 | O40: =IFERROR((NPV(O$34,$F$23:$J$23) + PV(O$34,$H$1,,-(UFCF_Yr5*(1+$G40)/(O$34-$G40)),0) - $C$36)/$C$39, "Error") -> 297.53951 | ... Q40: =IFERROR((NPV(Q$34,$F$23:$J$23) + PV(Q$34,$H$1,,-(UFCF_Yr5*(1+$G40)/(Q$34-$G40)),0) - $C$36)/$C$39, "Error") -> 221.70125
B41: Equity Value Per Share | C41: =C37/C39 -> 128.43758 | G41: =G40+$H$29 -> 0.055 | H41: =IFERROR((NPV(H$34,$F$23:$J$23) + PV(H$34,$H$1,,-(UFCF_Yr5*(1+$G41)/(H$34-$G41)),0) - $C$36)/$C$39, "Error") -> -898.03654 | I41: =IFERROR((NPV(I$34,$F$23:$J$23) + PV(I$34,$H$1,,-(UFCF_Yr5*(1+$G41)/(I$34-$G41)),0) - $C$36)/$C$39, "Error") -> -1790.8011 | J41: =IFERROR((NPV(J$34,$F$23:$J$23) + PV(J$34,$H$1,,-(UFCF_Yr5*(1+$G41)/(J$34-$G41)),0) - $C$36)/$C$39, "Error") -> Error | K41: =IFERROR((NPV(K$34,$F$23:$J$23) + PV(K$34,$H$1,,-(UFCF_Yr5*(1+$G41)/(K$34-$G41)),0) - $C$36)/$C$39, "Error") -> 1780.1835 | L41: =IFERROR((NPV(L$34,$F$23:$J$23) + PV(L$34,$H$1,,-(UFCF_Yr5*(1+$G41)/(L$34-$G41)),0) - $C$36)/$C$39, "Error") -> 887.41953 | M41: =IFERROR((NPV(M$34,$F$23:$J$23) + PV(M$34,$H$1,,-(UFCF_Yr5*(1+$G41)/(M$34-$G41)),0) - $C$36)/$C$39, "Error") -> 589.82385 | N41: =IFERROR((NPV(N$34,$F$23:$J$23) + PV(N$34,$H$1,,-(UFCF_Yr5*(1+$G41)/(N$34-$G41)),0) - $C$36)/$C$39, "Error") -> 441.02039 | O41: =IFERROR((NPV(O$34,$F$23:$J$23) + PV(O$34,$H$1,,-(UFCF_Yr5*(1+$G41)/(O$34-$G41)),0) - $C$36)/$C$39, "Error") -> 351.73392 | ... Q41: =IFERROR((NPV(Q$34,$F$23:$J$23) + PV(Q$34,$H$1,,-(UFCF_Yr5*(1+$G41)/(Q$34-$G41)),0) - $C$36)/$C$39, "Error") -> 249.68312
G42: =G41+$H$29 -> 0.06 | H42: =IFERROR((NPV(H$34,$F$23:$J$23) + PV(H$34,$H$1,,-(UFCF_Yr5*(1+$G42)/(H$34-$G42)),0) - $C$36)/$C$39, "Error") -> -588.89714 | I42: =IFERROR((NPV(I$34,$F$23:$J$23) + PV(I$34,$H$1,,-(UFCF_Yr5*(1+$G42)/(I$34-$G42)),0) - $C$36)/$C$39, "Error") -> -880.92227 | J42: =IFERROR((NPV(J$34,$F$23:$J$23) + PV(J$34,$H$1,,-(UFCF_Yr5*(1+$G42)/(J$34-$G42)),0) - $C$36)/$C$39, "Error") -> -1756.9649 | K42: =IFERROR((NPV(K$34,$F$23:$J$23) + PV(K$34,$H$1,,-(UFCF_Yr5*(1+$G42)/(K$34-$G42)),0) - $C$36)/$C$39, "Error") -> Error | L42: =IFERROR((NPV(L$34,$F$23:$J$23) + PV(L$34,$H$1,,-(UFCF_Yr5*(1+$G42)/(L$34-$G42)),0) - $C$36)/$C$39, "Error") -> 1747.1105 | M42: =IFERROR((NPV(M$34,$F$23:$J$23) + PV(M$34,$H$1,,-(UFCF_Yr5*(1+$G42)/(M$34-$G42)),0) - $C$36)/$C$39, "Error") -> 871.06859 | N42: =IFERROR((NPV(N$34,$F$23:$J$23) + PV(N$34,$H$1,,-(UFCF_Yr5*(1+$G42)/(N$34-$G42)),0) - $C$36)/$C$39, "Error") -> 579.04472 | O42: =IFERROR((NPV(O$34,$F$23:$J$23) + PV(O$34,$H$1,,-(UFCF_Yr5*(1+$G42)/(O$34-$G42)),0) - $C$36)/$C$39, "Error") -> 433.02554 | ... Q42: =IFERROR((NPV(Q$34,$F$23:$J$23) + PV(Q$34,$H$1,,-(UFCF_Yr5*(1+$G42)/(Q$34-$G42)),0) - $C$36)/$C$39, "Error") -> 286.99229
G43: =G42+$H$29 -> 0.065 | H43: =IFERROR((NPV(H$34,$F$23:$J$23) + PV(H$34,$H$1,,-(UFCF_Yr5*(1+$G43)/(H$34-$G43)),0) - $C$36)/$C$39, "Error") -> -434.32744 | I43: =IFERROR((NPV(I$34,$F$23:$J$23) + PV(I$34,$H$1,,-(UFCF_Yr5*(1+$G43)/(I$34-$G43)),0) - $C$36)/$C$39, "Error") -> -577.62932 | J43: =IFERROR((NPV(J$34,$F$23:$J$23) + PV(J$34,$H$1,,-(UFCF_Yr5*(1+$G43)/(J$34-$G43)),0) - $C$36)/$C$39, "Error") -> -864.21269 | K43: =IFERROR((NPV(K$34,$F$23:$J$23) + PV(K$34,$H$1,,-(UFCF_Yr5*(1+$G43)/(K$34-$G43)),0) - $C$36)/$C$39, "Error") -> -1723.923 | L43: =IFERROR((NPV(L$34,$F$23:$J$23) + PV(L$34,$H$1,,-(UFCF_Yr5*(1+$G43)/(L$34-$G43)),0) - $C$36)/$C$39, "Error") -> Error | M43: =IFERROR((NPV(M$34,$F$23:$J$23) + PV(M$34,$H$1,,-(UFCF_Yr5*(1+$G43)/(M$34-$G43)),0) - $C$36)/$C$39, "Error") -> 1714.8028 | N43: =IFERROR((NPV(N$34,$F$23:$J$23) + PV(N$34,$H$1,,-(UFCF_Yr5*(1+$G43)/(N$34-$G43)),0) - $C$36)/$C$39, "Error") -> 855.0934 | O43: =IFERROR((NPV(O$34,$F$23:$J$23) + PV(O$34,$H$1,,-(UFCF_Yr5*(1+$G43)/(O$34-$G43)),0) - $C$36)/$C$39, "Error") -> 568.51156 | ... Q43: =IFERROR((NPV(Q$34,$F$23:$J$23) + PV(Q$34,$H$1,,-(UFCF_Yr5*(1+$G43)/(Q$34-$G43)),0) - $C$36)/$C$39, "Error") -> 339.22511
B44: Implied EBITDA Terminal Multiple | G44: =G43+$H$29 -> 0.07 | H44: =IFERROR((NPV(H$34,$F$23:$J$23) + PV(H$34,$H$1,,-(UFCF_Yr5*(1+$G44)/(H$34-$G44)),0) - $C$36)/$C$39, "Error") -> -341.58562 | I44: =IFERROR((NPV(I$34,$F$23:$J$23) + PV(I$34,$H$1,,-(UFCF_Yr5*(1+$G44)/(I$34-$G44)),0) - $C$36)/$C$39, "Error") -> -425.98284 | J44: =IFERROR((NPV(J$34,$F$23:$J$23) + PV(J$34,$H$1,,-(UFCF_Yr5*(1+$G44)/(J$34-$G44)),0) - $C$36)/$C$39, "Error") -> -566.62862 | K44: =IFERROR((NPV(K$34,$F$23:$J$23) + PV(K$34,$H$1,,-(UFCF_Yr5*(1+$G44)/(K$34-$G44)),0) - $C$36)/$C$39, "Error") -> -847.89638 | L44: =IFERROR((NPV(L$34,$F$23:$J$23) + PV(L$34,$H$1,,-(UFCF_Yr5*(1+$G44)/(L$34-$G44)),0) - $C$36)/$C$39, "Error") -> -1691.6533 | M44: =IFERROR((NPV(M$34,$F$23:$J$23) + PV(M$34,$H$1,,-(UFCF_Yr5*(1+$G44)/(M$34-$G44)),0) - $C$36)/$C$39, "Error") -> Error | N44: =IFERROR((NPV(N$34,$F$23:$J$23) + PV(N$34,$H$1,,-(UFCF_Yr5*(1+$G44)/(N$34-$G44)),0) - $C$36)/$C$39, "Error") -> 1683.2394 | O44: =IFERROR((NPV(O$34,$F$23:$J$23) + PV(O$34,$H$1,,-(UFCF_Yr5*(1+$G44)/(O$34-$G44)),0) - $C$36)/$C$39, "Error") -> 839.48361 | ... Q44: =IFERROR((NPV(Q$34,$F$23:$J$23) + PV(Q$34,$H$1,,-(UFCF_Yr5*(1+$G44)/(Q$34-$G44)),0) - $C$36)/$C$39, "Error") -> 417.57435
B45: Terminal year UFCF | C45: =UFCF_Yr5 -> 2223.5174
...

Sheet Multiples
A1: *Note: Do not change any non-yellow cells or non-blue text | F1: NPER: | G1: =Assumptions!J5-Assumptions!E5 -> 5
A2: Figures in millions, except per share
B5: EBITDA Multiple Method | H5: Price Sensitivity Analysis
B7: Weighted average cost of capital: | C7: =WACC -> 0.098564437 | H7: TerminalMultiple increment
B8: Net present value of free cash flow | C8: =NPV(C7,DCF!F23:J23) -> 7796.0897 | H8: 0.5
H9: WACC increment
B10: Comp multiple | C10: 8.5 | H10: 0.005
B11: Terminal value | C11: =C10*Yr5_EBITDA -> 35169.715
B12: Present value of the terminal value | C12: =PV(WACC,G1,,-C11,0) -> 21980.682 | H12: WACC
G13: =C20 -> 141.45862 | H13: 0.05 | I13: =H13+$H$10 -> 0.055 | J13: =I13+$H$10 -> 0.06 | K13: =J13+$H$10 -> 0.065 | L13: =K13+$H$10 -> 0.07 | M13: =L13+$H$10 -> 0.075 | N13: =M13+$H$10 -> 0.08 | O13: =N13+$H$10 -> 0.085 | P13: =O13+$H$10 -> 0.09 | Q13: =P13+$H$10 -> 0.095
B14: Enterprise value | C14: =C8+C12 -> 29776.772 | F14: Terminal Multiple | G14: 5.5 | H14: =IFERROR((NPV(H$13,DCF!$F$23:$J$23) + PV(H$13,$G$1,,-$G14*Yr5_EBITDA,0)-$C$15)/$C$18, "Error") -> 126.31041 | I14: =IFERROR((NPV(I$13,DCF!$F$23:$J$23) + PV(I$13,$G$1,,-$G14*Yr5_EBITDA,0)-$C$15)/$C$18, "Error") -> 123.60815 | J14: =IFERROR((NPV(J$13,DCF!$F$23:$J$23) + PV(J$13,$G$1,,-$G14*Yr5_EBITDA,0)-$C$15)/$C$18, "Error") -> 120.97775 | K14: =IFERROR((NPV(K$13,DCF!$F$23:$J$23) + PV(K$13,$G$1,,-$G14*Yr5_EBITDA,0)-$C$15)/$C$18, "Error") -> 118.41694 | L14: =IFERROR((NPV(L$13,DCF!$F$23:$J$23) + PV(L$13,$G$1,,-$G14*Yr5_EBITDA,0)-$C$15)/$C$18, "Error") -> 115.92353 | M14: =IFERROR((NPV(M$13,DCF!$F$23:$J$23) + PV(M$13,$G$1,,-$G14*Yr5_EBITDA,0)-$C$15)/$C$18, "Error") -> 113.4954 | N14: =IFERROR((NPV(N$13,DCF!$F$23:$J$23) + PV(N$13,$G$1,,-$G14*Yr5_EBITDA,0)-$C$15)/$C$18, "Error") -> 111.13052 | O14: =IFERROR((NPV(O$13,DCF!$F$23:$J$23) + PV(O$13,$G$1,,-$G14*Yr5_EBITDA,0)-$C$15)/$C$18, "Error") -> 108.82692 | ... Q14: =IFERROR((NPV(Q$13,DCF!$F$23:$J$23) + PV(Q$13,$G$1,,-$G14*Yr5_EBITDA,0)-$C$15)/$C$18, "Error") -> 104.39605
B15: Less: Net debt* | C15: 1336.8 | G15: =G14+$H$8 -> 6 | H15: =IFERROR((NPV(H$13,DCF!$F$23:$J$23) + PV(H$13,$G$1,,-$G15*Yr5_EBITDA,0)-$C$15)/$C$18, "Error") -> 134.37298 | I15: =IFERROR((NPV(I$13,DCF!$F$23:$J$23) + PV(I$13,$G$1,,-$G15*Yr5_EBITDA,0)-$C$15)/$C$18, "Error") -> 131.48147 | J15: =IFERROR((NPV(J$13,DCF!$F$23:$J$23) + PV(J$13,$G$1,,-$G15*Yr5_EBITDA,0)-$C$15)/$C$18, "Error") -> 128.66712 | K15: =IFERROR((NPV(K$13,DCF!$F$23:$J$23) + PV(K$13,$G$1,,-$G15*Yr5_EBITDA,0)-$C$15)/$C$18, "Error") -> 125.9275 | L15: =IFERROR((NPV(L$13,DCF!$F$23:$J$23) + PV(L$13,$G$1,,-$G15*Yr5_EBITDA,0)-$C$15)/$C$18, "Error") -> 123.26024 | M15: =IFERROR((NPV(M$13,DCF!$F$23:$J$23) + PV(M$13,$G$1,,-$G15*Yr5_EBITDA,0)-$C$15)/$C$18, "Error") -> 120.66307 | N15: =IFERROR((NPV(N$13,DCF!$F$23:$J$23) + PV(N$13,$G$1,,-$G15*Yr5_EBITDA,0)-$C$15)/$C$18, "Error") -> 118.1338 | O15: =IFERROR((NPV(O$13,DCF!$F$23:$J$23) + PV(O$13,$G$1,,-$G15*Yr5_EBITDA,0)-$C$15)/$C$18, "Error") -> 115.67031 | ... Q15: =IFERROR((NPV(Q$13,DCF!$F$23:$J$23) + PV(Q$13,$G$1,,-$G15*Yr5_EBITDA,0)-$C$15)/$C$18, "Error") -> 110.93261
B16: Equity value | C16: =C14-C15 -> 28439.972 | G16: =G15+$H$8 -> 6.5 | H16: =IFERROR((NPV(H$13,DCF!$F$23:$J$23) + PV(H$13,$G$1,,-$G16*Yr5_EBITDA,0)-$C$15)/$C$18, "Error") -> 142.43556 | I16: =IFERROR((NPV(I$13,DCF!$F$23:$J$23) + PV(I$13,$G$1,,-$G16*Yr5_EBITDA,0)-$C$15)/$C$18, "Error") -> 139.35479 | J16: =IFERROR((NPV(J$13,DCF!$F$23:$J$23) + PV(J$13,$G$1,,-$G16*Yr5_EBITDA,0)-$C$15)/$C$18, "Error") -> 136.35649 | K16: =IFERROR((NPV(K$13,DCF!$F$23:$J$23) + PV(K$13,$G$1,,-$G16*Yr5_EBITDA,0)-$C$15)/$C$18, "Error") -> 133.43806 | L16: =IFERROR((NPV(L$13,DCF!$F$23:$J$23) + PV(L$13,$G$1,,-$G16*Yr5_EBITDA,0)-$C$15)/$C$18, "Error") -> 130.59695 | M16: =IFERROR((NPV(M$13,DCF!$F$23:$J$23) + PV(M$13,$G$1,,-$G16*Yr5_EBITDA,0)-$C$15)/$C$18, "Error") -> 127.83074 | N16: =IFERROR((NPV(N$13,DCF!$F$23:$J$23) + PV(N$13,$G$1,,-$G16*Yr5_EBITDA,0)-$C$15)/$C$18, "Error") -> 125.13708 | O16: =IFERROR((NPV(O$13,DCF!$F$23:$J$23) + PV(O$13,$G$1,,-$G16*Yr5_EBITDA,0)-$C$15)/$C$18, "Error") -> 122.51371 | ... Q16: =IFERROR((NPV(Q$13,DCF!$F$23:$J$23) + PV(Q$13,$G$1,,-$G16*Yr5_EBITDA,0)-$C$15)/$C$18, "Error") -> 117.46918
G17: =G16+$H$8 -> 7 | H17: =IFERROR((NPV(H$13,DCF!$F$23:$J$23) + PV(H$13,$G$1,,-$G17*Yr5_EBITDA,0)-$C$15)/$C$18, "Error") -> 150.49813 | I17: =IFERROR((NPV(I$13,DCF!$F$23:$J$23) + PV(I$13,$G$1,,-$G17*Yr5_EBITDA,0)-$C$15)/$C$18, "Error") -> 147.2281 | J17: =IFERROR((NPV(J$13,DCF!$F$23:$J$23) + PV(J$13,$G$1,,-$G17*Yr5_EBITDA,0)-$C$15)/$C$18, "Error") -> 144.04586 | K17: =IFERROR((NPV(K$13,DCF!$F$23:$J$23) + PV(K$13,$G$1,,-$G17*Yr5_EBITDA,0)-$C$15)/$C$18, "Error") -> 140.94861 | L17: =IFERROR((NPV(L$13,DCF!$F$23:$J$23) + PV(L$13,$G$1,,-$G17*Yr5_EBITDA,0)-$C$15)/$C$18, "Error") -> 137.93366 | M17: =IFERROR((NPV(M$13,DCF!$F$23:$J$23) + PV(M$13,$G$1,,-$G17*Yr5_EBITDA,0)-$C$15)/$C$18, "Error") -> 134.99841 | N17: =IFERROR((NPV(N$13,DCF!$F$23:$J$23) + PV(N$13,$G$1,,-$G17*Yr5_EBITDA,0)-$C$15)/$C$18, "Error") -> 132.14036 | O17: =IFERROR((NPV(O$13,DCF!$F$23:$J$23) + PV(O$13,$G$1,,-$G17*Yr5_EBITDA,0)-$C$15)/$C$18, "Error") -> 129.3571 | ... Q17: =IFERROR((NPV(Q$13,DCF!$F$23:$J$23) + PV(Q$13,$G$1,,-$G17*Yr5_EBITDA,0)-$C$15)/$C$18, "Error") -> 124.00574
B18: Diluted shares: | C18: 201.048 | G18: =G17+$H$8 -> 7.5 | H18: =IFERROR((NPV(H$13,DCF!$F$23:$J$23) + PV(H$13,$G$1,,-$G18*Yr5_EBITDA,0)-$C$15)/$C$18, "Error") -> 158.5607 | I18: =IFERROR((NPV(I$13,DCF!$F$23:$J$23) + PV(I$13,$G$1,,-$G18*Yr5_EBITDA,0)-$C$15)/$C$18, "Error") -> 155.10142 | J18: =IFERROR((NPV(J$13,DCF!$F$23:$J$23) + PV(J$13,$G$1,,-$G18*Yr5_EBITDA,0)-$C$15)/$C$18, "Error") -> 151.73523 | K18: =IFERROR((NPV(K$13,DCF!$F$23:$J$23) + PV(K$13,$G$1,,-$G18*Yr5_EBITDA,0)-$C$15)/$C$18, "Error") -> 148.45917 | L18: =IFERROR((NPV(L$13,DCF!$F$23:$J$23) + PV(L$13,$G$1,,-$G18*Yr5_EBITDA,0)-$C$15)/$C$18, "Error") -> 145.27037 | M18: =IFERROR((NPV(M$13,DCF!$F$23:$J$23) + PV(M$13,$G$1,,-$G18*Yr5_EBITDA,0)-$C$15)/$C$18, "Error") -> 142.16607 | N18: =IFERROR((NPV(N$13,DCF!$F$23:$J$23) + PV(N$13,$G$1,,-$G18*Yr5_EBITDA,0)-$C$15)/$C$18, "Error") -> 139.14364 | O18: =IFERROR((NPV(O$13,DCF!$F$23:$J$23) + PV(O$13,$G$1,,-$G18*Yr5_EBITDA,0)-$C$15)/$C$18, "Error") -> 136.20049 | ... Q18: =IFERROR((NPV(Q$13,DCF!$F$23:$J$23) + PV(Q$13,$G$1,,-$G18*Yr5_EBITDA,0)-$C$15)/$C$18, "Error") -> 130.54231
G19: =G18+$H$8 -> 8 | H19: =IFERROR((NPV(H$13,DCF!$F$23:$J$23) + PV(H$13,$G$1,,-$G19*Yr5_EBITDA,0)-$C$15)/$C$18, "Error") -> 166.62328 | I19: =IFERROR((NPV(I$13,DCF!$F$23:$J$23) + PV(I$13,$G$1,,-$G19*Yr5_EBITDA,0)-$C$15)/$C$18, "Error") -> 162.97474 | J19: =IFERROR((NPV(J$13,DCF!$F$23:$J$23) + PV(J$13,$G$1,,-$G19*Yr5_EBITDA,0)-$C$15)/$C$18, "Error") -> 159.42461 | K19: =IFERROR((NPV(K$13,DCF!$F$23:$J$23) + PV(K$13,$G$1,,-$G19*Yr5_EBITDA,0)-$C$15)/$C$18, "Error") -> 155.96973 | L19: =IFERROR((NPV(L$13,DCF!$F$23:$J$23) + PV(L$13,$G$1,,-$G19*Yr5_EBITDA,0)-$C$15)/$C$18, "Error") -> 152.60708 | M19: =IFERROR((NPV(M$13,DCF!$F$23:$J$23) + PV(M$13,$G$1,,-$G19*Yr5_EBITDA,0)-$C$15)/$C$18, "Error") -> 149.33374 | N19: =IFERROR((NPV(N$13,DCF!$F$23:$J$23) + PV(N$13,$G$1,,-$G19*Yr5_EBITDA,0)-$C$15)/$C$18, "Error") -> 146.14691 | O19: =IFERROR((NPV(O$13,DCF!$F$23:$J$23) + PV(O$13,$G$1,,-$G19*Yr5_EBITDA,0)-$C$15)/$C$18, "Error") -> 143.04389 | ... Q19: =IFERROR((NPV(Q$13,DCF!$F$23:$J$23) + PV(Q$13,$G$1,,-$G19*Yr5_EBITDA,0)-$C$15)/$C$18, "Error") -> 137.07887
B20: Equity Value Per Share | C20: =C16/C18 -> 141.45862 | G20: =G19+$H$8 -> 8.5 | H20: =IFERROR((NPV(H$13,DCF!$F$23:$J$23) + PV(H$13,$G$1,,-$G20*Yr5_EBITDA,0)-$C$15)/$C$18, "Error") -> 174.68585 | I20: =IFERROR((NPV(I$13,DCF!$F$23:$J$23) + PV(I$13,$G$1,,-$G20*Yr5_EBITDA,0)-$C$15)/$C$18, "Error") -> 170.84806 | J20: =IFERROR((NPV(J$13,DCF!$F$23:$J$23) + PV(J$13,$G$1,,-$G20*Yr5_EBITDA,0)-$C$15)/$C$18, "Error") -> 167.11398 | K20: =IFERROR((NPV(K$13,DCF!$F$23:$J$23) + PV(K$13,$G$1,,-$G20*Yr5_EBITDA,0)-$C$15)/$C$18, "Error") -> 163.48028 | L20: =IFERROR((NPV(L$13,DCF!$F$23:$J$23) + PV(L$13,$G$1,,-$G20*Yr5_EBITDA,0)-$C$15)/$C$18, "Error") -> 159.94378 | M20: =IFERROR((NPV(M$13,DCF!$F$23:$J$23) + PV(M$13,$G$1,,-$G20*Yr5_EBITDA,0)-$C$15)/$C$18, "Error") -> 156.50141 | N20: =IFERROR((NPV(N$13,DCF!$F$23:$J$23) + PV(N$13,$G$1,,-$G20*Yr5_EBITDA,0)-$C$15)/$C$18, "Error") -> 153.15019 | O20: =IFERROR((NPV(O$13,DCF!$F$23:$J$23) + PV(O$13,$G$1,,-$G20*Yr5_EBITDA,0)-$C$15)/$C$18, "Error") -> 149.88728 | ... Q20: =IFERROR((NPV(Q$13,DCF!$F$23:$J$23) + PV(Q$13,$G$1,,-$G20*Yr5_EBITDA,0)-$C$15)/$C$18, "Error") -> 143.61544
G21: =G20+$H$8 -> 9 | H21: =IFERROR((NPV(H$13,DCF!$F$23:$J$23) + PV(H$13,$G$1,,-$G21*Yr5_EBITDA,0)-$C$15)/$C$18, "Error") -> 182.74842 | I21: =IFERROR((NPV(I$13,DCF!$F$23:$J$23) + PV(I$13,$G$1,,-$G21*Yr5_EBITDA,0)-$C$15)/$C$18, "Error") -> 178.72138 | J21: =IFERROR((NPV(J$13,DCF!$F$23:$J$23) + PV(J$13,$G$1,,-$G21*Yr5_EBITDA,0)-$C$15)/$C$18, "Error") -> 174.80335 | K21: =IFERROR((NPV(K$13,DCF!$F$23:$J$23) + PV(K$13,$G$1,,-$G21*Yr5_EBITDA,0)-$C$15)/$C$18, "Error") -> 170.99084 | L21: =IFERROR((NPV(L$13,DCF!$F$23:$J$23) + PV(L$13,$G$1,,-$G21*Yr5_EBITDA,0)-$C$15)/$C$18, "Error") -> 167.28049 | M21: =IFERROR((NPV(M$13,DCF!$F$23:$J$23) + PV(M$13,$G$1,,-$G21*Yr5_EBITDA,0)-$C$15)/$C$18, "Error") -> 163.66908 | N21: =IFERROR((NPV(N$13,DCF!$F$23:$J$23) + PV(N$13,$G$1,,-$G21*Yr5_EBITDA,0)-$C$15)/$C$18, "Error") -> 160.15347 | O21: =IFERROR((NPV(O$13,DCF!$F$23:$J$23) + PV(O$13,$G$1,,-$G21*Yr5_EBITDA,0)-$C$15)/$C$18, "Error") -> 156.73067 | ... Q21: =IFERROR((NPV(Q$13,DCF!$F$23:$J$23) + PV(Q$13,$G$1,,-$G21*Yr5_EBITDA,0)-$C$15)/$C$18, "Error") -> 150.152
G22: =G21+$H$8 -> 9.5 | H22: =IFERROR((NPV(H$13,DCF!$F$23:$J$23) + PV(H$13,$G$1,,-$G22*Yr5_EBITDA,0)-$C$15)/$C$18, "Error") -> 190.811 | I22: =IFERROR((NPV(I$13,DCF!$F$23:$J$23) + PV(I$13,$G$1,,-$G22*Yr5_EBITDA,0)-$C$15)/$C$18, "Error") -> 186.5947 | J22: =IFERROR((NPV(J$13,DCF!$F$23:$J$23) + PV(J$13,$G$1,,-$G22*Yr5_EBITDA,0)-$C$15)/$C$18, "Error") -> 182.49272 | K22: =IFERROR((NPV(K$13,DCF!$F$23:$J$23) + PV(K$13,$G$1,,-$G22*Yr5_EBITDA,0)-$C$15)/$C$18, "Error") -> 178.5014 | L22: =IFERROR((NPV(L$13,DCF!$F$23:$J$23) + PV(L$13,$G$1,,-$G22*Yr5_EBITDA,0)-$C$15)/$C$18, "Error") -> 174.6172 | M22: =IFERROR((NPV(M$13,DCF!$F$23:$J$23) + PV(M$13,$G$1,,-$G22*Yr5_EBITDA,0)-$C$15)/$C$18, "Error") -> 170.83674 | N22: =IFERROR((NPV(N$13,DCF!$F$23:$J$23) + PV(N$13,$G$1,,-$G22*Yr5_EBITDA,0)-$C$15)/$C$18, "Error") -> 167.15675 | O22: =IFERROR((NPV(O$13,DCF!$F$23:$J$23) + PV(O$13,$G$1,,-$G22*Yr5_EBITDA,0)-$C$15)/$C$18, "Error") -> 163.57406 | ... Q22: =IFERROR((NPV(Q$13,DCF!$F$23:$J$23) + PV(Q$13,$G$1,,-$G22*Yr5_EBITDA,0)-$C$15)/$C$18, "Error") -> 156.68857
B23: Implied Perpetuity Growth Rate | G23: =G22+$H$8 -> 10 | H23: =IFERROR((NPV(H$13,DCF!$F$23:$J$23) + PV(H$13,$G$1,,-$G23*Yr5_EBITDA,0)-$C$15)/$C$18, "Error") -> 198.87357 | I23: =IFERROR((NPV(I$13,DCF!$F$23:$J$23) + PV(I$13,$G$1,,-$G23*Yr5_EBITDA,0)-$C$15)/$C$18, "Error") -> 194.46802 | J23: =IFERROR((NPV(J$13,DCF!$F$23:$J$23) + PV(J$13,$G$1,,-$G23*Yr5_EBITDA,0)-$C$15)/$C$18, "Error") -> 190.18209 | K23: =IFERROR((NPV(K$13,DCF!$F$23:$J$23) + PV(K$13,$G$1,,-$G23*Yr5_EBITDA,0)-$C$15)/$C$18, "Error") -> 186.01195 | L23: =IFERROR((NPV(L$13,DCF!$F$23:$J$23) + PV(L$13,$G$1,,-$G23*Yr5_EBITDA,0)-$C$15)/$C$18, "Error") -> 181.95391 | M23: =IFERROR((NPV(M$13,DCF!$F$23:$J$23) + PV(M$13,$G$1,,-$G23*Yr5_EBITDA,0)-$C$15)/$C$18, "Error") -> 178.00441 | N23: =IFERROR((NPV(N$13,DCF!$F$23:$J$23) + PV(N$13,$G$1,,-$G23*Yr5_EBITDA,0)-$C$15)/$C$18, "Error") -> 174.16003 | O23: =IFERROR((NPV(O$13,DCF!$F$23:$J$23) + PV(O$13,$G$1,,-$G23*Yr5_EBITDA,0)-$C$15)/$C$18, "Error") -> 170.41746 | ... Q23: =IFERROR((NPV(Q$13,DCF!$F$23:$J$23) + PV(Q$13,$G$1,,-$G23*Yr5_EBITDA,0)-$C$15)/$C$18, "Error") -> 163.22513
B24: Terminal year EBITDA | C24: =Yr5_EBITDA -> 4137.6135
B25: Weighted average cost of capital | C25: =WACC -> 0.098564437
B26: Multiple | C26: =C10 -> 8.5
B27: Terminal year unlevered free cash flow | C27: =UFCF_Yr5 -> 2223.5174 | E27: TV | F27: = | G27: FCF | H27: *(1+g)/(wacc-g)
B28: Implied Growth Rate: | C28: 0.0245016 | E28: =C11 -> 35169.715 | F28: = | G28: =C27*(1+C28)/(WACC-C28) -> 30757.627
