Workbook

Sheet Saas Model
D1: g_salary | E1: 0.1
D2: g_COGs | E2: 0.05
A3: Discount rate | B3: 0.0885 | D3: Avg Checks per user | E3: 19
A4: Tax rate | B4: 0.21 | D4: Subscription cost | E4: 1.4
A5: Long term growth | B5: 0.025 | D5: Check Transaction Revenue Revenue | E5: 0.55
A6: # of Banks | B6: 25
D8: Years
B9: Year | C9: Month 1 | D9: 1 | E9: 2 | F9: 3 | G9: 4 | H9: 5
A10: Revenue | B10: Subscription Fees | D10: =12*$E$4*D51 -> 997634.4 | E10: =12*$E$4*E51 -> 1354500 | F10: =12*$E$4*F51 -> 1839012 | G10: =12*$E$4*G51 -> 2496849.6 | H10: =12*$E$4*H51 -> 3390004.8
B11: Check Transaction Fees | D11: =12*$E$3*$E$5*D51 -> 7446628.2 | E11: =12*$E$3*$E$5*E51 -> 10110375 | F11: =12*$E$3*$E$5*F51 -> 13726911 | G11: =12*$E$3*$E$5*G51 -> 18637199 | H11: =12*$E$3*$E$5*H51 -> 25303964
B16: Total Revenue | C16: =SUM(C10:C11) -> 0 | D16: =SUM(D10:D15) -> 8444262.6 | E16: =SUM(E10:E15) -> 11464875 | F16: =SUM(F10:F15) -> 15565923 | G16: =SUM(G10:G15) -> 21134048 | H16: =SUM(H10:H15) -> 28693969
A17: COGS | B17: Domains, servers | C17: 4200 | D17: =C17*12 -> 50400 | E17: =D17*(1+$E$2) -> 52920 | F17: =E17*(1+$E$2) -> 55566 | G17: =F17*(1+$E$2) -> 58344.3 | H17: =G17*(1+$E$2) -> 61261.515
B18: IT MSFT Services 800-number | C18: 5000 | D18: 61700 | E18: =D18*(1+$E$2) -> 64785 | F18: =E18*(1+$E$2) -> 68024.25 | G18: =F18*(1+$E$2) -> 71425.463 | H18: =G18*(1+$E$2) -> 74996.736
B19: Misc | C19: 500 | D19: =C19*12 -> 6000 | E19: =D19*(1+E48) -> 8146.2679 | F19: =E19*(1+F48) -> 11060.28 | G19: =F19*(1+G48) -> 15016.668 | H19: =G19*(1+H48) -> 20388.299
B24: Total COGS | D24: =SUM(D17:D19) -> 118100 | E24: =SUM(E17:E19) -> 125851.27 | F24: =SUM(F17:F19) -> 134650.53 | G24: =SUM(G17:G19) -> 144786.43 | H24: =SUM(H17:H19) -> 156646.55
B25: Gross Profit | D25: =D16-D24 -> 8326162.6 | E25: =E16-E24 -> 11339024 | F25: =F16-F24 -> 15431272 | G25: =G16-G24 -> 20989262 | H25: =H16-H24 -> 28537323
A26: Expenses | B26: Salary | D26: 155000 | E26: =D26*(1+$E$1) -> 170500 | F26: =E26*(1+$E$1) -> 187550 | G26: =F26*(1+$E$1) -> 206305 | H26: =G26*(1+$E$1) -> 226935.5
B27: Integration, App Improvement, Marketing | C27: 31000 | D27: =C27*(1+D48) -> 42089.051 | E27: =D27*(1+E48) -> 57144.781 | F27: =E27*(1+F48) -> 77586.115 | G27: =F27*(1+G48) -> 105339.55 | H27: =G27*(1+H48) -> 143020.7
B31: Total Expenses | D31: =SUM(D26:D28) -> 197089.05 | E31: =SUM(E26:E28) -> 227644.78 | F31: =SUM(F26:F28) -> 265136.12 | G31: =SUM(G26:G28) -> 311644.55 | H31: =SUM(H26:H28) -> 369956.2
B32: EBITDA | D32: =D25-D31 -> 8129073.5 | E32: =E25-E31 -> 11111379 | F32: =F25-F31 -> 15166136 | G32: =G25-G31 -> 20677617 | H32: =H25-H31 -> 28167366
B33: D&A
B34: EBIT | D34: =D32-D33 -> 8129073.5 | E34: =E32-E33 -> 11111379 | F34: =F32-F33 -> 15166136 | G34: =G32-G33 -> 20677617 | H34: =H32-H33 -> 28167366
B35: Interest
B36: EBT | D36: =D34-D35 -> 8129073.5 | E36: =E34-E35 -> 11111379 | F36: =F34-F35 -> 15166136 | G36: =G34-G35 -> 20677617 | H36: =H34-H35 -> 28167366
B37: Taxes | D37: =MAX(0,$B$4*D36) -> 1707105.4 | E37: =MAX(0,$B$4*E36) -> 2333389.6 | F37: =MAX(0,$B$4*F36) -> 3184888.6 | G37: =MAX(0,$B$4*G36) -> 4342299.7 | H37: =MAX(0,$B$4*H36) -> 5915147
B38: FCF | D38: =D36-D37 -> 6421968.1 | E38: =E36-E37 -> 8777989.4 | F38: =F36-F37 -> 11981248 | G38: =G36-G37 -> 16335318 | H38: =H36-H37 -> 22252219
B39: Terminal Val | H39: =H38*(1+B5)/(B3-B5) -> 3.5918937e+08
B40: PV(FCF) | D40: =PV($B$3,D9,,-D38,0) -> 5899832.9 | E40: =PV($B$3,E9,,-E38,0) -> 7408634.7 | F40: =PV($B$3,F9,,-F38,0) -> 9290022.1 | G40: =PV($B$3,G9,,-G38,0) -> 11636272 | H40: =-PV($B$3,H9,,H38+H39,0) -> 2.4962373e+08
A42: Enterprise Value | B42: =SUM(D40:H40) -> 2.838585e+08
B46: Assumptions
D47: =D9 -> 1 | E47: =E9 -> 2 | F47: =F9 -> 3 | G47: =G9 -> 4 | H47: =H9 -> 5
B48: Subscription Growth | D48: 0.35771132 | E48: =D48 -> 0.35771132 | F48: =E48 -> 0.35771132 | G48: =F48 -> 0.35771132 | H48: =G48 -> 0.35771132
B49: Check transaction growth | D49: =D48 -> 0.35771132 | E49: =E48 -> 0.35771132 | F49: =F48 -> 0.35771132 | G49: =G48 -> 0.35771132 | H49: =H48 -> 0.35771132
B51: Users | D51: =SUM('Company Growth'!D14) -> 59383 | E51: =ROUND(D51*(1+E48),0) -> 80625 | F51: =ROUND(E51*(1+F48),0) -> 109465 | G51: =ROUND(F51*(1+G48),0) -> 148622 | H51: =ROUND(G51*(1+H48),0) -> 201786
B52: Gross Margin | D52: =D25/D16 -> 0.98601417 | E52: =E25/E16 -> 0.98902288 | F52: =F25/F16 -> 0.99134966 | G52: =G25/G16 -> 0.99314914 | H52: =H25/H16 -> 0.99454078
B54: SENSITIVITY (Discount Rate vs Growth Rate)
D55: Growth Rate (Long term)
C56: =B42 -> 2.838585e+08 | D56: 0 | E56: 0.025 | F56: 0.05 | G56: 0.075 | H56: 0.1
B57: Discount Rate | C57: 0.01 | D57: 2.1806848e+09 | E57: -1.3833062e+09 | F57: -4.9230843e+08 | G57: -2.8669356e+08 | H57: -1.9530918e+08
C58: 0.02 | D58: 1.0689952e+09 | E58: -4.0704076e+09 | F58: -6.4413902e+08 | G58: -3.3266007e+08 | H58: -2.1585546e+08
...

Sheet Model with partnerships
A1: Note: Only Yellow Cells are Changeable | F1: Basic | H1: Licensing & Maintenaance | J1: Private Label
D2: g_salary | E2: 0.1 | F2: Cost | G2: 0 | H2: Cost | I2: 25000 | J2: Cost | K2: 13000
A3: Discount rate | B3: 0.095 | D3: g_COGs | E3: 0.05 | F3: Fee Retained | G3: 0.3 | H3: Fee Retained | I3: 0.3 | J3: Fee Retained | K3: 0.3
A4: Tax rate | B4: 0.21 | D4: Avg Checks per user | E4: 19 | F4: Commission | H4: Commission | I4: 0.35 | J4: Commission | K4: 0.35
A5: Long term growth | B5: 0.03 | D5: Subscription cost | E5: 1.4 | F5: Sales Rep | G5: 0.02 | H5: Sales Rep | I5: 0.02 | J5: Sales Rep | K5: 0.035
A6: # of Banks | B6: 50 | D6: Check Transaction Revenue | E6: 0.55 | F6: Revenue share | G6: 0.56 | H6: Revenue share | I6: 0.4 | J6: Revenue share
A7: Users per bank | B7: 5000
D8: Years
B9: Year | D9: 1 | E9: 2 | F9: 3 | G9: 4 | H9: 5
A10: Revenue | B10: Subscription Fees | D10: =12*$E$5*D53 -> 997634.4 | E10: =12*$E$5*E53 -> 1147272 | F10: =12*$E$5*F53 -> 1319371.2 | G10: =12*$E$5*G53 -> 1517275.2 | H10: =12*$E$5*H53 -> 1744864.8
B11: Check Transaction Fees | D11: =12*$E$4*$E$6*D53 -> 7446628.2 | E11: =12*$E$4*$E$6*E53 -> 8563566 | F11: =12*$E$4*$E$6*F53 -> 9848163.6 | G11: =12*$E$4*$E$6*G53 -> 11325376 | H11: =12*$E$4*$E$6*H53 -> 13024169
B12: Private Label | D12: =$K$2*D59 -> 0 | E12: =$K$2*E59 -> 26000 | F12: =$K$2*F59 -> 26000 | G12: =$K$2*G59 -> 26000 | H12: =$K$2*H59 -> 26000
B13: Private Label transaction fee | D13: =12*$E$4*$K$3*D68 -> 0 | E13: =12*$E$4*$K$3*E68 -> 136800 | F13: =12*$E$4*$K$3*F68 -> 273600 | G13: =12*$E$4*$K$3*G68 -> 410400 | H13: =12*$E$4*$K$3*H68 -> 547200
B14: Licensing Agreement | D14: =$I$2*D58 -> 0 | E14: =$I$2*E58 -> 25000 | F14: =$I$2*F58 -> 25000 | G14: =$I$2*G58 -> 50000 | H14: =$I$2*H58 -> 50000
B15: L & M transaction fee | D15: =12*$E$4*$I$3*D67 -> 0 | E15: =12*$E$4*$I$3*E67 -> 68400 | F15: =12*$E$4*$I$3*F67 -> 136800 | G15: =12*$E$4*$I$3*G67 -> 273600 | H15: =12*$E$4*$I$3*H67 -> 410400
B16: Direct Marketing model | D16: =12*$E$4*$G$3*D66 -> 2052 | E16: =12*$E$4*$G$3*E66 -> 275652 | F16: =12*$E$4*$G$3*F66 -> 549252 | G16: =12*$E$4*$G$3*G66 -> 822852 | H16: =12*$E$4*$G$3*H66 -> 1096452
B17: Total Revenue | D17: =SUM(D10:D16) -> 8446314.6 | E17: =SUM(E10:E16) -> 10242690 | F17: =SUM(F10:F16) -> 12178187 | G17: =SUM(G10:G16) -> 14425503 | H17: =SUM(H10:H16) -> 16899086
A18: COGS | B18: Domains, servers | C18: 4200 | D18: =C18*12 -> 50400 | E18: =D18*(1+$E$3) -> 52920 | F18: =E18*(1+$E$3) -> 55566 | G18: =F18*(1+$E$3) -> 58344.3 | H18: =G18*(1+$E$3) -> 61261.515
B19: IT Support | C19: 5000 | D19: 61700 | E19: =D19*(1+$E$3) -> 64785 | F19: =E19*(1+$E$3) -> 68024.25 | G19: =F19*(1+$E$3) -> 71425.463 | H19: =G19*(1+$E$3) -> 74996.736
B20: Misc | C20: 500 | D20: =C20*12 -> 6000 | E20: =D20*(1+E50) -> 6900 | F20: =E20*(1+F50) -> 7935 | G20: =F20*(1+G50) -> 9125.25 | H20: =G20*(1+H50) -> 10494.037
B21: Private Label Commission | D21: =$K$4*$K$2*D59 -> 0 | E21: =$K$4*$K$2*E59 -> 9100 | F21: =$K$4*$K$2*F59 -> 9100 | G21: =$K$4*$K$2*G59 -> 9100 | H21: =$K$4*$K$2*H59 -> 9100
B22: Private Label Sales Reps | D22: =SUM('Partnership breakdown'!B25:M25) -> 0 | E22: =SUM('Partnership breakdown'!N25:Y25) -> 12703.27 | F22: =SUM('Partnership breakdown'!Z25:AK25) -> 12703.27 | G22: =SUM('Partnership breakdown'!AL25:AW25) -> 12703.27 | H22: =SUM('Partnership breakdown'!AX25:BI25) -> 12703.27
B23: License & maintenance Commission | D23: =$I$4*$I$2*D58 -> 0 | E23: =$I$4*$I$2*E58 -> 8750 | F23: =$I$4*$I$2*F58 -> 8750 | G23: =$I$4*$I$2*G58 -> 17500 | H23: =$I$4*$I$2*H58 -> 17500
B24: License & maintenance Sales Reps | D24: =SUM('Partnership breakdown'!B24:M24) -> 0 | E24: =SUM('Partnership breakdown'!N24:Y24) -> 6351.6349 | F24: =SUM('Partnership breakdown'!Z24:AK24) -> 6351.6349 | G24: =SUM('Partnership breakdown'!AL24:AW24) -> 12703.27 | H24: =SUM('Partnership breakdown'!AX24:BI24) -> 12703.27
B25: Reoccuring Commission (Sales Rep) | D25: =SUM('Partnership breakdown'!B23:M23) -> 190.54905 | E25: =SUM('Partnership breakdown'!N23:Y23) -> 25406.54 | F25: =SUM('Partnership breakdown'!Z23:AK23) -> 25406.54 | G25: =SUM('Partnership breakdown'!AL23:AW23) -> 25406.54 | H25: =SUM('Partnership breakdown'!AX23:BI23) -> 25406.54
B26: Total COGS | D26: =SUM(D18:D25) -> 118290.55 | E26: =SUM(E18:E25) -> 186916.44 | F26: =SUM(F18:F25) -> 193836.69 | G26: =SUM(G18:G25) -> 216308.09 | H26: =SUM(H18:H25) -> 224165.37
B27: Gross Profit | D27: =D17-D26 -> 8328024.1 | E27: =E17-E26 -> 10055774 | F27: =F17-F26 -> 11984350 | G27: =G17-G26 -> 14209195 | H27: =H17-H26 -> 16674921
A28: Expenses | B28: Salary | D28: 155000 | E28: =D28*(1+$E$2) -> 170500 | F28: =E28*(1+$E$2) -> 187550 | G28: =F28*(1+$E$2) -> 206305 | H28: =G28*(1+$E$2) -> 226935.5
B29: Integration, App Improvement, Marketing | C29: 31000 | D29: =C29*(1+D50) -> 35650 | E29: =D29*(1+E50) -> 40997.5 | F29: =E29*(1+F50) -> 47147.125 | G29: =F29*(1+G50) -> 54219.194 | H29: =G29*(1+H50) -> 62352.073
B33: Total Expenses | D33: =SUM(D28:D32) -> 190650 | E33: =SUM(E28:E32) -> 211497.5 | F33: =SUM(F28:F32) -> 234697.13 | G33: =SUM(G28:G32) -> 260524.19 | H33: =SUM(H28:H32) -> 289287.57
B34: EBITDA | D34: =D27-D33 -> 8137374.1 | E34: =E27-E33 -> 9844276.1 | F34: =F27-F33 -> 11749653 | G34: =G27-G33 -> 13948671 | H34: =H27-H33 -> 16385633
B35: D&A
B36: EBIT | D36: =D34-D35 -> 8137374.1 | E36: =E34-E35 -> 9844276.1 | F36: =F34-F35 -> 11749653 | G36: =G34-G35 -> 13948671 | H36: =H34-H35 -> 16385633
B37: Interest
B38: EBT | D38: =D36-D37 -> 8137374.1 | E38: =E36-E37 -> 9844276.1 | F38: =F36-F37 -> 11749653 | G38: =G36-G37 -> 13948671 | H38: =H36-H37 -> 16385633
B39: Taxes | D39: =MAX(0,$B$4*D38) -> 1708848.6 | E39: =MAX(0,$B$4*E38) -> 2067298 | F39: =MAX(0,$B$4*F38) -> 2467427.1 | G39: =MAX(0,$B$4*G38) -> 2929220.8 | H39: =MAX(0,$B$4*H38) -> 3440983
B40: FCF | D40: =D38-D39 -> 6428525.5 | E40: =E38-E39 -> 7776978.1 | F40: =F38-F39 -> 9282225.9 | G40: =G38-G39 -> 11019450 | H40: =H38-H39 -> 12944650
B41: Terminal Val | H41: =H40*(1+B5)/(B3-B5) -> 2.0512292e+08
B42: PV(FCF) | D42: =PV($B$3,D9,,-D40,0) -> 5870799.5 | E42: =PV($B$3,E9,,-E40,0) -> 6486085 | F42: =PV($B$3,F9,,-F40,0) -> 7069843.1 | G42: =PV($B$3,G9,,-G40,0) -> 7664845.9 | H42: =-PV($B$3,H9,,H40+H41,0) -> 1.3852255e+08
A44: Enterprise Value | B44: =SUM(D42:H42) -> 1.6561413e+08
...

Sheet Partnership breakdown
A1: This tab contains the breakdown of the revenues per month for each partnership type
A2: The "Revenue per month" table contains the present value of 18 months of future cashflows from the new transactions of that month
A3: These are summed up and reflected in "Model with partnerships"
A6: Sales Rep Breakdown
B8: Total Transactions
A9: Year | B9: 1 | C9: 2 | D9: 3 | E9: 4 | F9: 5
A10: ='Model with partnerships'!B57 -> Basic | B10: ='Model with partnerships'!$E$4*'Model with partnerships'!D62 -> 570 | C10: ='Model with partnerships'!$E$4*'Model with partnerships'!E62 -> 76000 | D10: ='Model with partnerships'!$E$4*'Model with partnerships'!F62 -> 76000 | E10: ='Model with partnerships'!$E$4*'Model with partnerships'!G62 -> 76000 | F10: ='Model with partnerships'!$E$4*'Model with partnerships'!H62 -> 76000
A11: ='Model with partnerships'!B58 -> License & Maintenance | B11: ='Model with partnerships'!$E$4*'Model with partnerships'!D63 -> 0 | C11: ='Model with partnerships'!$E$4*'Model with partnerships'!E63 -> 19000 | D11: ='Model with partnerships'!$E$4*'Model with partnerships'!F63 -> 19000 | E11: ='Model with partnerships'!$E$4*'Model with partnerships'!G63 -> 38000 | F11: ='Model with partnerships'!$E$4*'Model with partnerships'!H63 -> 38000
A12: ='Model with partnerships'!B59 -> Private Label | B12: ='Model with partnerships'!$E$4*'Model with partnerships'!D64 -> 0 | C12: ='Model with partnerships'!$E$4*'Model with partnerships'!E64 -> 38000 | D12: ='Model with partnerships'!$E$4*'Model with partnerships'!F64 -> 38000 | E12: ='Model with partnerships'!$E$4*'Model with partnerships'!G64 -> 38000 | F12: ='Model with partnerships'!$E$4*'Model with partnerships'!H64 -> 38000
B14: Transactions per month
A15: Month | B15: {=_xlfn.SEQUENCE(1,60,1,1)} -> 1 | C15: 2 | D15: 3 | E15: 4 | F15: 5 | G15: 6 | H15: 7 | I15: 8 | J15: 9 | K15: 10 | L15: 11 | M15: 12 | N15: 13 | O15: 14 | P15: 15 | Q15: 16 | R15: 17 | S15: 18 | T15: 19 | U15: 20 | V15: 21 | W15: 22 | X15: 23 | Y15: 24 | Z15: 25 | AA15: 26 | AB15: 27 | AC15: 28 | AD15: 29 | AE15: 30 | AF15: 31 | AG15: 32 | AH15: 33 | AI15: 34 | AJ15: 35 | AK15: 36 | AL15: 37 | AM15: 38 | AN15: 39 | AO15: 40 | AP15: 41 | AQ15: 42 | AR15: 43 | AS15: 44 | AT15: 45 | AU15: 46 | AV15: 47 | AW15: 48 | AX15: 49 | AY15: 50 | AZ15: 51 | BA15: 52 | BB15: 53 | BC15: 54 | BD15: 55 | BE15: 56 | BF15: 57 | BG15: 58 | BH15: 59 | BI15: 60
A16: ="New Transactions"&" ("&A10&")" -> New Transactions (Basic) | B16: =$B10/12 -> 47.5 | C16: =$B10/12 -> 47.5 | D16: =$B10/12 -> 47.5 | E16: =$B10/12 -> 47.5 | F16: =$B10/12 -> 47.5 | G16: =$B10/12 -> 47.5 | H16: =$B10/12 -> 47.5 | I16: =$B10/12 -> 47.5 | ... M16: =$B10/12 -> 47.5 | N16: =$C10/12 -> 6333.3333 | O16: =$C10/12 -> 6333.3333 | P16: =$C10/12 -> 6333.3333 | Q16: =$C10/12 -> 6333.3333 | R16: =$C10/12 -> 6333.3333 | S16: =$C10/12 -> 6333.3333 | T16: =$C10/12 -> 6333.3333 | U16: =$C10/12 -> 6333.3333 | ... Y16: =$C10/12 -> 6333.3333 | Z16: =$D10/12 -> 6333.3333 | AA16: =$D10/12 -> 6333.3333 | AB16: =$D10/12 -> 6333.3333 | AC16: =$D10/12 -> 6333.3333 | AD16: =$D10/12 -> 6333.3333 | AE16: =$D10/12 -> 6333.3333 | AF16: =$D10/12 -> 6333.3333 | AG16: =$D10/12 -> 6333.3333 | ... AK16: =$D10/12 -> 6333.3333 | AL16: =$E10/12 -> 6333.3333 | AM16: =$E10/12 -> 6333.3333 | AN16: =$E10/12 -> 6333.3333 | AO16: =$E10/12 -> 6333.3333 | AP16: =$E10/12 -> 6333.3333 | AQ16: =$E10/12 -> 6333.3333 | AR16: =$E10/12 -> 6333.3333 | AS16: =$E10/12 -> 6333.3333 | ... AW16: =$E10/12 -> 6333.3333 | AX16: =$F10/12 -> 6333.3333 | AY16: =$F10/12 -> 6333.3333 | AZ16: =$F10/12 -> 6333.3333 | BA16: =$F10/12 -> 6333.3333 | BB16: =$F10/12 -> 6333.3333 | BC16: =$F10/12 -> 6333.3333 | BD16: =$F10/12 -> 6333.3333 | BE16: =$F10/12 -> 6333.3333 | ... BI16: =$F10/12 -> 6333.3333
A17: ="New Transactions"&" ("&A11&")" -> New Transactions (License & Maintenance) | B17: =$B11/12 -> 0 | C17: =$B11/12 -> 0 | D17: =$B11/12 -> 0 | E17: =$B11/12 -> 0 | F17: =$B11/12 -> 0 | G17: =$B11/12 -> 0 | H17: =$B11/12 -> 0 | I17: =$B11/12 -> 0 | ... M17: =$B11/12 -> 0 | N17: =$C11/12 -> 1583.3333 | O17: =$C11/12 -> 1583.3333 | P17: =$C11/12 -> 1583.3333 | Q17: =$C11/12 -> 1583.3333 | R17: =$C11/12 -> 1583.3333 | S17: =$C11/12 -> 1583.3333 | T17: =$C11/12 -> 1583.3333 | U17: =$C11/12 -> 1583.3333 | ... Y17: =$C11/12 -> 1583.3333 | Z17: =$D11/12 -> 1583.3333 | AA17: =$D11/12 -> 1583.3333 | AB17: =$D11/12 -> 1583.3333 | AC17: =$D11/12 -> 1583.3333 | AD17: =$D11/12 -> 1583.3333 | AE17: =$D11/12 -> 1583.3333 | AF17: =$D11/12 -> 1583.3333 | AG17: =$D11/12 -> 1583.3333 | ... AK17: =$D11/12 -> 1583.3333 | AL17: =$E11/12 -> 3166.6667 | AM17: =$E11/12 -> 3166.6667 | AN17: =$E11/12 -> 3166.6667 | AO17: =$E11/12 -> 3166.6667 | AP17: =$E11/12 -> 3166.6667 | AQ17: =$E11/12 -> 3166.6667 | AR17: =$E11/12 -> 3166.6667 | AS17: =$E11/12 -> 3166.6667 | ... AW17: =$E11/12 -> 3166.6667 | AX17: =$F11/12 -> 3166.6667 | AY17: =$F11/12 -> 3166.6667 | AZ17: =$F11/12 -> 3166.6667 | BA17: =$F11/12 -> 3166.6667 | BB17: =$F11/12 -> 3166.6667 | BC17: =$F11/12 -> 3166.6667 | BD17: =$F11/12 -> 3166.6667 | BE17: =$F11/12 -> 3166.6667 | ... BI17: =$F11/12 -> 3166.6667
A18: ="New Transactions"&" ("&A12&")" -> New Transactions (Private Label) | B18: =$B12/12 -> 0 | C18: =$B12/12 -> 0 | D18: =$B12/12 -> 0 | E18: =$B12/12 -> 0 | F18: =$B12/12 -> 0 | G18: =$B12/12 -> 0 | H18: =$B12/12 -> 0 | I18: =$B12/12 -> 0 | ... M18: =$B12/12 -> 0 | N18: =$C12/12 -> 3166.6667 | O18: =$C12/12 -> 3166.6667 | P18: =$C12/12 -> 3166.6667 | Q18: =$C12/12 -> 3166.6667 | R18: =$C12/12 -> 3166.6667 | S18: =$C12/12 -> 3166.6667 | T18: =$C12/12 -> 3166.6667 | U18: =$C12/12 -> 3166.6667 | ... Y18: =$C12/12 -> 3166.6667 | Z18: =$D12/12 -> 3166.6667 | AA18: =$D12/12 -> 3166.6667 | AB18: =$D12/12 -> 3166.6667 | AC18: =$D12/12 -> 3166.6667 | AD18: =$D12/12 -> 3166.6667 | AE18: =$D12/12 -> 3166.6667 | AF18: =$D12/12 -> 3166.6667 | AG18: =$D12/12 -> 3166.6667 | ... AK18: =$D12/12 -> 3166.6667 | AL18: =$E12/12 -> 3166.6667 | AM18: =$E12/12 -> 3166.6667 | AN18: =$E12/12 -> 3166.6667 | AO18: =$E12/12 -> 3166.6667 | AP18: =$E12/12 -> 3166.6667 | AQ18: =$E12/12 -> 3166.6667 | AR18: =$E12/12 -> 3166.6667 | AS18: =$E12/12 -> 3166.6667 | ... AW18: =$E12/12 -> 3166.6667 | AX18: =$F12/12 -> 3166.6667 | AY18: =$F12/12 -> 3166.6667 | AZ18: =$F12/12 -> 3166.6667 | BA18: =$F12/12 -> 3166.6667 | BB18: =$F12/12 -> 3166.6667 | BC18: =$F12/12 -> 3166.6667 | BD18: =$F12/12 -> 3166.6667 | BE18: =$F12/12 -> 3166.6667 | ... BI18: =$F12/12 -> 3166.6667
B21: Revenue per month
A22: Month | B22: {=_xlfn.SEQUENCE(1,60,1,1)} -> 1 | C22: 2 | D22: 3 | E22: 4 | F22: 5 | G22: 6 | H22: 7 | I22: 8 | J22: 9 | K22: 10 | L22: 11 | M22: 12 | N22: 13 | O22: 14 | P22: 15 | Q22: 16 | R22: 17 | S22: 18 | T22: 19 | U22: 20 | V22: 21 | W22: 22 | X22: 23 | Y22: 24 | Z22: 25 | AA22: 26 | AB22: 27 | AC22: 28 | AD22: 29 | AE22: 30 | AF22: 31 | AG22: 32 | AH22: 33 | AI22: 34 | AJ22: 35 | AK22: 36 | AL22: 37 | AM22: 38 | AN22: 39 | AO22: 40 | AP22: 41 | AQ22: 42 | AR22: 43 | AS22: 44 | AT22: 45 | AU22: 46 | AV22: 47 | AW22: 48 | AX22: 49 | AY22: 50 | AZ22: 51 | BA22: 52 | BB22: 53 | BC22: 54 | BD22: 55 | BE22: 56 | BF22: 57 | BG22: 58 | BH22: 59 | BI22: 60
A23: ="Transactions"&" ("&A10&")" -> Transactions (Basic) | B23: =-PV('Model with partnerships'!$B$3/12,18,'Model with partnerships'!$G$5*B16,,0) -> 15.879087 | C23: =-PV('Model with partnerships'!$B$3/12,18,'Model with partnerships'!$G$5*C16,,0) -> 15.879087 | D23: =-PV('Model with partnerships'!$B$3/12,18,'Model with partnerships'!$G$5*D16,,0) -> 15.879087 | E23: =-PV('Model with partnerships'!$B$3/12,18,'Model with partnerships'!$G$5*E16,,0) -> 15.879087 | F23: =-PV('Model with partnerships'!$B$3/12,18,'Model with partnerships'!$G$5*F16,,0) -> 15.879087 | G23: =-PV('Model with partnerships'!$B$3/12,18,'Model with partnerships'!$G$5*G16,,0) -> 15.879087 | H23: =-PV('Model with partnerships'!$B$3/12,18,'Model with partnerships'!$G$5*H16,,0) -> 15.879087 | I23: =-PV('Model with partnerships'!$B$3/12,18,'Model with partnerships'!$G$5*I16,,0) -> 15.879087 | ... BI23: =-PV('Model with partnerships'!$B$3/12,18,'Model with partnerships'!$G$5*BI16,,0) -> 2117.2116
A24: ="Transactions"&" ("&A11&")" -> Transactions (License & Maintenance) | B24: =-PV('Model with partnerships'!$B$3/12,18,'Model with partnerships'!$G$5*B17,,0) -> 0 | C24: =-PV('Model with partnerships'!$B$3/12,18,'Model with partnerships'!$G$5*C17,,0) -> 0 | D24: =-PV('Model with partnerships'!$B$3/12,18,'Model with partnerships'!$G$5*D17,,0) -> 0 | E24: =-PV('Model with partnerships'!$B$3/12,18,'Model with partnerships'!$G$5*E17,,0) -> 0 | F24: =-PV('Model with partnerships'!$B$3/12,18,'Model with partnerships'!$G$5*F17,,0) -> 0 | G24: =-PV('Model with partnerships'!$B$3/12,18,'Model with partnerships'!$G$5*G17,,0) -> 0 | H24: =-PV('Model with partnerships'!$B$3/12,18,'Model with partnerships'!$G$5*H17,,0) -> 0 | I24: =-PV('Model with partnerships'!$B$3/12,18,'Model with partnerships'!$G$5*I17,,0) -> 0 | ... BI24: =-PV('Model with partnerships'!$B$3/12,18,'Model with partnerships'!$G$5*BI17,,0) -> 1058.6058
A25: ="Transactions"&" ("&A12&")" -> Transactions (Private Label) | B25: =-PV('Model with partnerships'!$B$3/12,18,'Model with partnerships'!$G$5*B18,,0) -> 0 | C25: =-PV('Model with partnerships'!$B$3/12,18,'Model with partnerships'!$G$5*C18,,0) -> 0 | D25: =-PV('Model with partnerships'!$B$3/12,18,'Model with partnerships'!$G$5*D18,,0) -> 0 | E25: =-PV('Model with partnerships'!$B$3/12,18,'Model with partnerships'!$G$5*E18,,0) -> 0 | F25: =-PV('Model with partnerships'!$B$3/12,18,'Model with partnerships'!$G$5*F18,,0) -> 0 | G25: =-PV('Model with partnerships'!$B$3/12,18,'Model with partnerships'!$G$5*G18,,0) -> 0 | H25: =-PV('Model with partnerships'!$B$3/12,18,'Model with partnerships'!$G$5*H18,,0) -> 0 | I25: =-PV('Model with partnerships'!$B$3/12,18,'Model with partnerships'!$G$5*I18,,0) -> 0 | ... BI25: =-PV('Model with partnerships'!$B$3/12,18,'Model with partnerships'!$G$5*BI18,,0) -> 1058.6058

Sheet Company Growth
A1: Our projected Growth Rate
A3: Expenses: Operating, SGA,etc
A4: Gross profit - Expenses = EBITDA
A5: EBITDA - D&A = EBIT
A6: EBIT - Taxes = NOPAT
A7: Add back D&A, subtract CAPEX, subtract change in NWC
A8: NWC - CA - CA
B11: 2021 End | C11: 2022 | D11: 2023 (Till Jul 15)
A12: Customers | B12: 8741 | C12: 26000 | D12: 32166
B13: 2021 | C13: 2022 | D13: 2023 Projected
A14: # Customers | B14: =B12 -> 8741 | C14: =C12 -> 26000 | D14: =ROUND(D12/(6.5/12),0) -> 59383
A15: Growth | C15: =(C14-B14)/B14 -> 1.974488 | D15: =(SUM(D14:D14)-C14)/C14 -> 1.2839615

Sheet Rates
A1: Growth Rates: | B1: Our Company
A2: ='Company Growth'!E15 -> 0 | C2: 1 | D2: 2 | E2: 3 | F2: 4 | G2: 5
B3: Subscrition Fee | C3: =A2 -> 0 | D3: =C3 -> 0 | E3: =D3 -> 0 | F3: =E3 -> 0 | G3: =F3 -> 0
B4: Check Fee | C4: =C3 -> 0 | D4: =D3 -> 0 | E4: =E3 -> 0 | F4: =F3 -> 0 | G4: =G3 -> 0
B6: This case takes the projected growth rate for the company this year and extends it through years 1-5
A8: Growth Rates: | B8: Paypal
A9: 0.17181246 | C9: 1 | D9: 2 | E9: 3 | F9: 4 | G9: 5
B10: Subscrition Fee | C10: =A9 -> 0.17181246 | D10: =C10 -> 0.17181246 | E10: =D10 -> 0.17181246 | F10: =E10 -> 0.17181246 | G10: =F10 -> 0.17181246
B11: Check Fee | C11: =C10 -> 0.17181246 | D11: =D10 -> 0.17181246 | E11: =E10 -> 0.17181246 | F11: =F10 -> 0.17181246 | G11: =G10 -> 0.17181246
B13: The conservative case takes the average growth rate of a mature industry competitor over 10 years (Paypal)
A16: Growth Rates: | B16: Bill Holdings
A17: 0.54361018 | C17: 1 | D17: 2 | E17: 3 | F17: 4 | G17: 5
B18: Subscrition Fee | C18: =$A$17 -> 0.54361018 | D18: =C18 -> 0.54361018 | E18: =D18 -> 0.54361018 | F18: =E18 -> 0.54361018 | G18: =F18 -> 0.54361018
B19: Check Fee | C19: =C18 -> 0.54361018 | D19: =D18 -> 0.54361018 | E19: =E18 -> 0.54361018 | F19: =F18 -> 0.54361018 | G19: =G18 -> 0.54361018
B21: The optimistic case takes the average growth of an industry competitor excluding an outlier year(Bill.com)
B22: Revenue data is available for just 5 years
A25: For Model
A26: 0.35771132 | B26: <--- This average of A9 & A17 is used for our valuations to keep it conservative

Sheet Competitor Growth & Margins
D1: 11 | E1: 10 | F1: 9 | G1: 8 | H1: 7 | I1: 6 | J1: 5 | K1: 4 | L1: 3 | M1: 2 | N1: 1
D2: 2022 | E2: 2021 | F2: 2020 | G2: 2019 | H2: 2018 | I2: 2017 | J2: 2016 | K2: 2015 | L2: 2014 | M2: 2013 | N2: 2012
C3: Paypal Revenue ($ mil) | D3: 27518 | E3: 25371 | F3: 21454 | G3: 17772 | H3: 15451 | I3: 13094 | J3: 10842 | K3: 9248 | L3: 8025 | M3: 6727 | N3: 5662
C5: Bill Holdings Revenue ($ mil) | D5: 2022 | E5: 2021 | F5: 2020 | G5: 2019 | H5: 2018
D6: 642 | E6: 238 | F6: 158 | G6: 108 | H6: 65
A8: Competitor growth | P8: Paypal Breakdown
D9: 2012 | E9: 2013 | F9: 2014 | G9: 2015 | H9: 2016 | I9: 2017 | J9: 2018 | K9: 2019 | L9: 2020 | M9: 2021 | N9: 2022 | Q9: Total Revenue | R9: Cost of Revenue | S9: Gross Profit | T9: Operating Expense | U9: Gross Margin
D10: 1 | E10: 2 | F10: 3 | G10: 4 | H10: 5 | I10: 6 | J10: 7 | K10: 8 | L10: 9 | M10: 10 | N10: 11 | P10: TTM | Q10: 27518000 | R10: 13745000 | S10: 13773000 | T10: 9729000 | U10: =S10/Q10 -> 0.50050876
C11: =C3 -> Paypal Revenue ($ mil) | D11: =HLOOKUP(D10,$D$1:$N$3,3,FALSE) -> 5662 | E11: =HLOOKUP(E10,$D$1:$N$3,3,FALSE) -> 6727 | F11: =HLOOKUP(F10,$D$1:$N$3,3,FALSE) -> 8025 | G11: =HLOOKUP(G10,$D$1:$N$3,3,FALSE) -> 9248 | H11: =HLOOKUP(H10,$D$1:$N$3,3,FALSE) -> 10842 | I11: =HLOOKUP(I10,$D$1:$N$3,3,FALSE) -> 13094 | J11: =HLOOKUP(J10,$D$1:$N$3,3,FALSE) -> 15451 | K11: =HLOOKUP(K10,$D$1:$N$3,3,FALSE) -> 17772 | ... N11: =HLOOKUP(N10,$D$1:$N$3,3,FALSE) -> 27518 | P11: 44926 | Q11: 27518000 | R11: 13745000 | S11: 13773000 | T11: 9729000 | U11: =S11/Q11 -> 0.50050876
C12: Growth | E12: =(E11-D11)/D11 -> 0.18809608 | F12: =(F11-E11)/E11 -> 0.19295377 | G12: =(G11-F11)/F11 -> 0.15239875 | H12: =(H11-G11)/G11 -> 0.17236159 | I12: =(I11-H11)/H11 -> 0.20771075 | J12: =(J11-I11)/I11 -> 0.18000611 | K12: =(K11-J11)/J11 -> 0.15021681 | L12: =(L11-K11)/K11 -> 0.20717983 | ... N12: =(N11-M11)/M11 -> 0.084624177 | P12: 44561 | Q12: 25371000 | R12: 11375000 | S12: 13996000 | T12: 9672000 | U12: =S12/Q12 -> 0.55165346
M13: Average | N13: =AVERAGE(E12:N12) -> 0.17181246 | P13: 44196 | Q13: 21454000 | R13: 9675000 | S13: 11779000 | T13: 8351000 | U13: =S13/Q13 -> 0.54903514
J14: =J9 -> 2018 | K14: =K9 -> 2019 | L14: =L9 -> 2020 | M14: =M9 -> 2021 | N14: =N9 -> 2022 | P14: 43830 | Q14: 17772000 | R14: 8170000 | S14: 9602000 | T14: 6812000 | U14: =S14/Q14 -> 0.54028809
C15: =C5 -> Bill Holdings Revenue ($ mil) | D15: =IF(HLOOKUP(D10,$D$1:$N$6,6,FALSE)=0,"",HLOOKUP(D10,$D$1:$N$6,6,FALSE)) | E15: =IF(HLOOKUP(E10,$D$1:$N$6,6,FALSE)=0,"",HLOOKUP(E10,$D$1:$N$6,6,FALSE)) | F15: =IF(HLOOKUP(F10,$D$1:$N$6,6,FALSE)=0,"",HLOOKUP(F10,$D$1:$N$6,6,FALSE)) | G15: =IF(HLOOKUP(G10,$D$1:$N$6,6,FALSE)=0,"",HLOOKUP(G10,$D$1:$N$6,6,FALSE)) | H15: =IF(HLOOKUP(H10,$D$1:$N$6,6,FALSE)=0,"",HLOOKUP(H10,$D$1:$N$6,6,FALSE)) | I15: =IF(HLOOKUP(I10,$D$1:$N$6,6,FALSE)=0,"",HLOOKUP(I10,$D$1:$N$6,6,FALSE)) | J15: =IF(HLOOKUP(J10,$D$1:$N$6,6,FALSE)=0,"",HLOOKUP(J10,$D$1:$N$6,6,FALSE)) -> 65 | K15: =IF(HLOOKUP(K10,$D$1:$N$6,6,FALSE)=0,"",HLOOKUP(K10,$D$1:$N$6,6,FALSE)) -> 108 | ... N15: =IF(HLOOKUP(N10,$D$1:$N$6,6,FALSE)=0,"",HLOOKUP(N10,$D$1:$N$6,6,FALSE)) -> 642 | T15: Average | U15: =AVERAGE(U10:U14) -> 0.52839884
C16: Growth | K16: =(K15-J15)/J15 -> 0.66153846 | L16: =(L15-K15)/K15 -> 0.46296296 | M16: =(M15-L15)/L15 -> 0.50632911 | N16: =(N15-M15)/M15 -> 1.697479
M17: Average | N17: =AVERAGE(K16:N16) -> 0.83207738 | P17: Bill Holdings Breakdown
M18: Average(exclude 2022) | N18: =AVERAGE(K16:M16) -> 0.54361018 | Q18: Total Revenue | R18: Operating Revenue | S18: Cost of Revenue | T18: Gross Profit | U18: Gross Margin
P19: TTM | Q19: 857062 | R19: 857062 | S19: 173358 | T19: 683704 | U19: =T19/Q19 -> 0.79772992
P20: 44742 | Q20: 641959 | R20: 641959 | S20: 145004 | T20: 496955 | U20: =T20/Q20 -> 0.77412265
P21: 44377 | Q21: 238265 | R21: 238265 | S21: 61806 | T21: 176459 | U21: =T21/Q21 -> 0.74059975
P22: 44012 | Q22: 157600 | R22: 157600 | S22: 39144 | T22: 118456 | U22: =T22/Q22 -> 0.75162437
T23: Average | U23: =AVERAGE(U19:U22) -> 0.76601917
T24: Average
A26: Sources
A27: Paypal: | B27: https://www.macrotrends.net/stocks/charts/PYPL/paypal-holdings/revenue
B28: https://finance.yahoo.com/quote/PYPL/financials?p=PYPL
A29: Bill: | B29: https://www.macrotrends.net/stocks/charts/BILL/bill-holdings/revenue
B30: https://finance.yahoo.com/quote/BILL/financials?p=BILL

Sheet WACC
B1: Bill | C1: Paypal | S1: SP500 returns last 10 years
A2: WACC | S2: 41639 | T2: 29.6
A3: Market Cap | B3: 13.29 billion | C3: 80.44 billion | S3: 42004 | T3: 11.39
S4: 42369 | T4: -0.73
S5: 42734 | T5: 9.54
A6: Source: alphaspread.com | S6: 43098 | T6: 19.42
S7: 43465 | T7: -6.24
A8: https://taxfoundation.org/combined-federal-state-corporate-tax-rates-2022/#:~:text=Corporations%20in%20the%20United%20States,at%20a%2021%20percent%20rate. | S8: 43830 | T8: 28.88
A9: US corporate tax rate is 21% | S9: 44196 | T9: 16.26
S10: 44561 | T10: 26.89
A11: Annual Salary growth averages (used last year's) | S11: 44926 | T11: -19.44
A12: https://www.ssa.gov/oact/cola/awidevelop.html | S12: Average | T12: =AVERAGE(T2:T11) -> 11.557
A13: riskfree rate: | B13: https://ycharts.com/indicators/20_year_treasury_rate#:~:text=20%20Year%20Treasury%20Rate%20is,a%20maturity%20of%2020%20years.
B15: Bill | C15: Paypal
A16: Beta (5Y Yahoo) | B16: 1.93 | C16: 1.32 | E16: risk-free rate | F16: 0.0411
A17: Cost of Equity | B17: =$F$16+(B16*($F$17-$F$16)) -> 0.1848271 | C17: =$F$16+(C16*($F$17-$F$16)) -> 0.1394004 | E17: SP500 avg return (10 yr) | F17: =T12/100 -> 0.11557
A18: Cost of debt | B18: 0.0435 | C18: 0.0505 | E18: Market risk premium | F18: =F17-F16 -> 0.07447 | Z18: V =2.29
A19: D/E Ratio | B19: 0.4404 | C19: 0.53 | E19: Tax Rate | F19: 0.21 | X19: D=1.29
A20: D/V | B20: =B19/(B19+1) -> 0.3057484 | C20: =C19/(C19+1) -> 0.34640523 | E20: WACC_Average unlevered | F20: =AVERAGE(B23:C23) -> 0.08847709 | X20: E=1
A21: E/V | B21: =1-B20 -> 0.6942516 | C21: =1-C20 -> 0.65359477
A22: WACC | B22: =(B21*B17)+(B20*B18*(1-$F$19)) -> 0.13882355 | C22: =(C21*C17)+(C20*C18*(1-$F$19)) -> 0.10493121
A23: WACC unlevered | B23: =B22/(1+((1-$F$19)*B20/B21)) -> 0.10299125 | C23: =C22/(1+((1-$F$19)*C20/C21)) -> 0.07396293 | Y23: D/V=1.29/2.29
A26: Paypal cost of debt | B26: https://cbonds.com/bonds/1278351/
A27: 10k Paypal | B27: https://s201.q4cdn.com/231198771/files/doc_financials/2023/ar/PayPal-Holdings-Inc-Combined-2023-Proxy-Statement-and-2022-Annual-Report.pdf
A28: 10k Bill | B28: https://s24.q4cdn.com/404137088/files/doc_financials/2022/q4/Bill.com-10K.pdf
A29: From Bill's 10k: | B29: "As of June 30, 2022, the interest rate on borrowings from the Class A facility was 4.35% per annum"
A30: Paypal D/E ratio | B30: https://www.morningstar.com/stocks/xnas/pypl/quote
A31: Bill D/E ratio | B31: https://www.wsj.com/market-data/quotes/BILL/financials | L31: WACC_unlevered = WACC_levered / (1 + ((1 - Tax Rate) * (D/E)))

Sheet Scribbles
B1: Customers | C1: 2023 | D1: Lost | F1: 243% growth 2022 | K1: 5 lost this year
B2: Jan | C2: 972 | D2: 1 | K2: 22 lost in 2022
B3: Feb | C3: 675 | D3: 2 | F3: add 17259 users | J3: 2023 | K3: 32166 active users | M3: in the middle of July | O3: (This is no partner activity…not including the bank stuff)
B4: Mar | C4: 795 | F4: from end of march at 8741 | M4: Think how much we assume we'll get from partners…and potentially add it to model
B5: Apr | C5: 798
B6: May | C6: 919 | M6: Space 25 banks over the 5 years (assume sign 6 banks every year, model 1 bank for this year…6 every year after). Conservative
B7: Jun | C7: 804 | M7: Can get 6 to 8 banks a year once momentum's gotten
B8: Jul | C8: 388 | D8: 2
M9: Assume average small - med bank has ~ 20,000..End: Customer writes 17.5 checks per month…review notes.
B10: Customers | C10: 2022 | D10: (active users) | M10: 35 cent transaction fee, 2 cents paid to sales rep from this for 18 months
B11: Jan | C11: 1447 | M11: Of the 33 cents, revenue can be shared back to the bank (keep 20c give bank 13c)
B12: Feb | C12: 1479
A13: 8741 beginning march 2022 | B13: Mar | C13: 1575 | K13: 32196 total users
A14: 17000+ added 2022 | B14: Apr | C14: 1664
B15: May | C15: 1623
B16: Jun | C16: 2261 | M16: Out of 6 banks, model 2 doing white label…the others doing the smaller approach
B17: Jul | C17: 2312 | M17: Add no white label for this year…next year add
B18: Aug | C18: 2421 | Z18: Models
B19: Sep | C19: 1912 | L19: Ne bank total | M19: 1 | N19: 6 | O19: 6 | P19: 6 | Q19: 6
B20: Oct | C20: 2082 | M20: Year 1 | N20: Year 2 | O20: Year 3 | P20: Year 4 | Q20: Year 5
B21: Nov | C21: 1752 | L21: White label | N21: 1 | O21: 3 | P21: 2 | Y21: Basic: | Z21: No white label, no licensing/maintenance, whole 35 cents…bank gets 20 cents, 2 cents to agent for at least 18 months
B22: Dec | C22: 2036 | L22: Lic | N22: 1 | P22: 2 | Z22: If relationship ends before 18 months, there are clawbacks in commission
L23: Main | O23: 1 | Z23: Figure out breakeven point so there's no need to clawback
L24: Remainder just revenue share…no 10k cost to get started | Z24: 10000 is the amount
A25: In 2021 we have 4,251 customers in 2022 we grew that to 25,666 currently we have currently we have 29,713 active customers we've only lost 29 customers. So total users we've had 29,742 so we have a combined growth rate right at at 92.2%. So I took a conservative approach with 30% | E25: L&M: License & maintenance | Z25: Assume average small - med bank has ~ 20,000..End: Customer writes 17.5 checks per month…review notes.
E26: 13 cents - bank revenue share | K26: This model we have doesn't take strategic partnerships…we want to model some of that in here as growth | Z26: 35 cent transaction fee, 2 cents paid to sales rep from this for 18 months
E27: Reoccuring bank revenue share was line for 13c going back to bank | K27: If we get 1 bank (banks have 20000 users…out of that how many do we get?) | Z27: Of the 33 cents, revenue can be shared back to the bank (keep 20c give bank 13c)
A28: 2021 | B28: 8741
A29: 17259 new customers in 8 months 2021 | K29: If we can get 5%, that's 1000 extra users | Y29: Licensing & Maintenance | Z29: 15000 one time as well
Z30: All these contracts are 24 - 36 months
L31: He wouldn't expect we get 1000 this year | Z31: 10% of banks assumed to take Licensing & maintenance, remaining go towards white label (out of the 50 banks)
L32: Lets call it 30 new from the bank this year then 1000 or more after
Y34: Q2 Banks | Z34: Group on banks within Q2 platforms
L35: NOTE: These are 24 to 36 month agreements | Z35: ~400 banks on their platform. We've committed to footing their costs
Z36: 2 paid cents to banks, and 2 cents Financial Institution (FI)
Z37: Use same logic. From 400 banks (assume 20 of those gotten), then model out 8 banks sending 17.5 checks per month
A39: This is a revenue | B39: White labeling = 10k a year
B40: 24 - 36 month agreement | L40: Models
B41: this 10k covers COGS, paying commission | Z41: 35c
B42: Need to figure out breakeven from commission | K42: Basic: | L42: No white label, no licensing/maintenance, whole 35 cents…bank gets 20 cents, 2 cents to agent for at least 18 months | Z42: 2c sales rep | AC42: Rep is only 18 months | AF42: …across all 3
...

Sheet NOTES
A1: To keep things simple, this valuation mainly references two close competitors: Paypal & Bill.com
A2: Discount rate was calculated by finding an average of unlevered WACC for Paypal & Bill after researching necessary components
A6: In terms of revenue growth, the conservative model averages Paypal (a mature company's) and BILL in the last 10 years
A7: It should be noted that the average Gross margin for Paypal in the last 10 years is 52.84%, and 76.6% for Bill excluding the outlier year. Our companie's is 98%+
A9: Domains, servers grow at same rate as subscriptions annually (except in yr 1)
A10: IT MSFT Services 800-number and Misc grow at g_COGS (E2)
A11: Salary in yr 1 is 155k, grows at 8.9% per year afterwards (Cell E1). Used most recent bls data to get this for the economy
A12: Expenses for integration, app improvement grow at same rate as subscriptions annually (except in yr 1)
A14: Long term growth assumed to be 2.5% (conservative estimation/inflation)
A15: Terminal growth rate assumed to be 2.5% as well (conservative)
A18: Model is based on getting 25 banks on board (1% of small to medium banks in the US, this is extremely conservative)
A20: Refer to sensitivity analyses at the bottom of the "Model" tab to see effect of changes on key assumptions
